Workbook

Sheet SETTING
B2: BPJS KESEHATAN | E2: PENGHASILAN TIDAK KENA PAJAK
B3: Batas Minimal Upah | C3: 4391337 | E3: TK/0 - Tidak kawin, 0 Tanggungan | F3: 54000000
B4: Batas Maksimal Upah | C4: 12000000 | E4: TK/1 - Tidak kawin, 1 Tanggungan | F4: 58500000
B5: Ditanggung Pemberi Kerja | C5: 0.04 | E5: TK/2 - Tidak kawin, 2 Tanggungan | F5: 63000000
B6: Ditanggung Tenaga Kerja | C6: 0.01 | E6: TK/3 - Tidak kawin, 3 Tanggungan | F6: 67500000
E7: K/0 - Kawin, 0 Tanggungan | F7: 58500000
B8: BPJS KETENAGAKERJAAN | E8: K/1 - Kawin, 1 Tanggungan | F8: 63000000
B9: Batas Maksimal Upah (JP) | C9: 11086300 | E9: K/2 - Kawin, 2 Tanggungan | F9: 67500000
B10: Jaminan Kecelakaan Kerja | C10: 0.0089 | E10: K/3 - Kawin, 3 Tanggungan | F10: 72000000
B11: Jaminan Kematian | C11: 0.003
B12: JHT Ditanggung Pemberi Kerja | C12: 0.037
B13: JHT Ditanggung Tenaga Kerja | C13: 0.02
B14: JP Ditanggung Pemberi Kerja | C14: 0.02
B15: JP Ditanggung Tenaga Kerja | C15: 0.01

Sheet TER 2024
A1: KATEGORI | B1: PENGHASILAN BRUTO | E1: TARIF
A2: KATEGORI A | B2: 0 | C2: s.d | D2: 5400000 | E2: 0
A3: KATEGORI A | B3: =D2+0.00001 -> 5400000 | C3: s.d | D3: 5650000 | E3: 0.0025
A4: KATEGORI A | B4: =D3+0.00001 -> 5650000 | C4: s.d | D4: 5950000 | E4: 0.005
A5: KATEGORI A | B5: =D4+0.00001 -> 5950000 | C5: s.d | D5: 6300000 | E5: 0.0075
A6: KATEGORI A | B6: =D5+0.00001 -> 6300000 | C6: s.d | D6: 6750000 | E6: 0.01
A7: KATEGORI A | B7: =D6+0.00001 -> 6750000 | C7: s.d | D7: 7500000 | E7: 0.0125
A8: KATEGORI A | B8: =D7+0.00001 -> 7500000 | C8: s.d | D8: 8550000 | E8: 0.015
A9: KATEGORI A | B9: =D8+0.00001 -> 8550000 | C9: s.d | D9: 9650000 | E9: 0.0175
A10: KATEGORI A | B10: =D9+0.00001 -> 9650000 | C10: s.d | D10: 10050000 | E10: 0.02
A11: KATEGORI A | B11: =D10+0.00001 -> 10050000 | C11: s.d | D11: 10350000 | E11: 0.0225
A12: KATEGORI A | B12: =D11+0.00001 -> 10350000 | C12: s.d | D12: 10700000 | E12: 0.025
A13: KATEGORI A | B13: =D12+0.00001 -> 10700000 | C13: s.d | D13: 11050000 | E13: 0.03
A14: KATEGORI A | B14: =D13+0.00001 -> 11050000 | C14: s.d | D14: 11600000 | E14: 0.035
... A44: KATEGORI A | B44: =D43+0.00001 -> 9.1e+08 | C44: s.d | D44: 1400000000 | E44: 0.33
A45: KATEGORI A | B45: =D44+0.00001 -> 1.4e+09 | D45: =D85 -> 999999999999999 | E45: 0.34
A46: KATEGORI B | B46: 0 | C46: s.d | D46: 6200000 | E46: 0
A47: KATEGORI B | B47: =D46+0.0001 -> 6200000 | C47: s.d | D47: 6500000 | E47: 0.0025
A48: KATEGORI B | B48: =D47+0.0001 -> 6500000 | C48: s.d | D48: 6850000 | E48: 0.005
A49: KATEGORI B | B49: =D48+0.0001 -> 6850000 | C49: s.d | D49: 7300000 | E49: 0.0075
A50: KATEGORI B | B50: =D49+0.0001 -> 7300000 | C50: s.d | D50: 9200000 | E50: 0.01
A51: KATEGORI B | B51: =D50+0.0001 -> 9200000 | C51: s.d | D51: 10750000 | E51: 0.015
A52: KATEGORI B | B52: =D51+0.0001 -> 10750000 | C52: s.d | D52: 11250000 | E52: 0.02
A53: KATEGORI B | B53: =D52+0.0001 -> 11250000 | C53: s.d | D53: 11600000 | E53: 0.025
A54: KATEGORI B | B54: =D53+0.0001 -> 11600000 | C54: s.d | D54: 12600000 | E54: 0.03
A55: KATEGORI B | B55: =D54+0.0001 -> 12600000 | C55: s.d | D55: 13600000 | E55: 0.04
A56: KATEGORI B | B56: =D55+0.0001 -> 13600000 | C56: s.d | D56: 14950000 | E56: 0.05
A57: KATEGORI B | B57: =D56+0.0001 -> 14950000 | C57: s.d | D57: 16400000 | E57: 0.06
A58: KATEGORI B | B58: =D57+0.0001 -> 16400000 | C58: s.d | D58: 18450000 | E58: 0.07
... A84: KATEGORI B | B84: =D83+0.0001 -> 9.57e+08 | C84: s.d | D84: 1405000000 | E84: 0.33
A85: KATEGORI B | B85: =D84+0.0001 -> 1.405e+09 | D85: 999999999999999 | E85: 0.34
A86: KATEGORI C | B86: 0 | C86: s.d | D86: 6600000 | E86: 0
A87: KATEGORI C | B87: =D86+0.00001 -> 6600000 | C87: s.d | D87: 6950000 | E87: 0.0025
A88: KATEGORI C | B88: =D87+0.00001 -> 6950000 | C88: s.d | D88: 7350000 | E88: 0.005
A89: KATEGORI C | B89: =D88+0.00001 -> 7350000 | C89: s.d | D89: 7800000 | E89: 0.0075
A90: KATEGORI C | B90: =D89+0.00001 -> 7800000 | C90: s.d | D90: 8850000 | E90: 0.01
A91: KATEGORI C | B91: =D90+0.00001 -> 8850000 | C91: s.d | D91: 9800000 | E91: 0.0125
A92: KATEGORI C | B92: =D91+0.00001 -> 9800000 | C92: s.d | D92: 10950000 | E92: 0.015
A93: KATEGORI C | B93: =D92+0.00001 -> 10950000 | C93: s.d | D93: 11200000 | E93: 0.0175
A94: KATEGORI C | B94: =D93+0.00001 -> 11200000 | C94: s.d | D94: 12050000 | E94: 0.02
...

Sheet TENAGA KERJA
A1: No | B1: Nama Tenaga Kerja | C1: NIP | D1: Jabatan | E1: Divisi | F1: Status Perpajakan | I1: Didaftarkan BPJS TK | J1: Didaftarkan BPJS Kes | K1: Gaji | L1: Tunjangan tetap | M1: lembur,THR, Bonus | N1: Natura, Dll | O1: THP | Q1: 1 | R1: LBR 1 X 1,5=….x1,5x1/173xgp/k.4 (klo ada tunj tetap) | S1: 2 | T1: LBR 2 X 2=….x2x1/173xgp/k.4 (klo ada tunj tetap) | U1: 3 | V1: LBR 3 X 3=….x3x1/173xgp/k.4(klo ada tunj tetap) | W1: 4 | X1: LBR 4X 4=….x3x1/173xgp/k.4(klo ada tunj tetap) | Y1: TTL LBR
A2: 1 | B2: ABDUL HALIM | C2: 222020 | E2: 1 | F2: NPWP | G2: K/3 | H2: =IF(OR(G2="TK/0",G2="TK/1",G2="K/0"),"KATEGORI A",IF(OR(G2="TK/2",G2="TK/3",G2="K/1",G2="K/2"),"KATEGORI B",IF(OR(G2="K/3"),"KATEGORI C",""))) -> KATEGORI C | I2: Ya | J2: Ya | K2: 2961337 | L2: =455000+325000+650000 -> 1430000 | M2: =+Y2 -> 1154947 | N2: =50000*31 -> 1550000 | O2: ='RINCIAN GAJI - GROSS'!W3 -> 6927922.9 | P2: aku buat sendiri | Q2: 13 | R2: =Q2*1.5*1/173*(K2+L2) -> 494977.29 | S2: 13 | T2: =S2*2*1/173*(K2+L2) -> 659969.72 | V2: =U2*3*1/173*4391337 -> 0 | X2: =W2*4*1/173*4391337 -> 0 | Y2: =R2+T2+V2+X2 -> 1154947
A3: =A2+1 -> 2 | B3: SRI ASLINDA | C3: K252070 | E3: =E2+1 -> 2 | F3: NPWP | G3: TK/0 | H3: =IF(OR(G3="TK/0",G3="TK/1",G3="K/0"),"KATEGORI A",IF(OR(G3="TK/2",G3="TK/3",G3="K/1",G3="K/2"),"KATEGORI B",IF(OR(G3="K/3"),"KATEGORI C",""))) -> KATEGORI A | I3: Ya | J3: Ya | K3: 2961337 | L3: =455000+325000+650000 -> 1430000 | M3: =+Y3+300000 -> 300000 | N3: =50000*31 -> 1550000 | O3: ='RINCIAN GAJI - GROSS'!W4 -> 6044904.4 | R3: =Q3*1.5*1/173*(K3+L3) -> 0 | T3: =S3*2*1/173*(K3+L3) -> 0 | V3: =U3*3*1/173*4391337 -> 0 | X3: =W3*4*1/173*4391337 -> 0 | Y3: =R3+T3+V3+X3 -> 0
A4: =A3+1 -> 3 | B4: RAFLY RAHMADAN GOBEL | C4: K262009 | E4: =E3+1 -> 3 | F4: NPWP | G4: TK/0 | H4: =IF(OR(G4="TK/0",G4="TK/1",G4="K/0"),"KATEGORI A",IF(OR(G4="TK/2",G4="TK/3",G4="K/1",G4="K/2"),"KATEGORI B",IF(OR(G4="K/3"),"KATEGORI C",""))) -> KATEGORI A | I4: Ya | J4: Ya | K4: 2961337 | L4: =455000+325000+650000 -> 1430000 | M4: =+Y4 -> 1231097.4 | N4: =50000*31 -> 1550000 | O4: ='RINCIAN GAJI - GROSS'!W5 -> 6948189.9 | Q4: 15 | R4: =Q4*1.5*1/173*(K4+L4) -> 571127.64 | S4: 13 | T4: =S4*2*1/173*(K4+L4) -> 659969.72 | V4: =U4*3*1/173*4391337 -> 0 | X4: =W4*4*1/173*4391337 -> 0 | Y4: =R4+T4+V4+X4 -> 1231097.4
A5: =A4+1 -> 4 | B5: RAHMAT HIDAYAT | C5: K262015 | E5: =E4+1 -> 4 | F5: NPWP | G5: TK/0 | H5: =IF(OR(G5="TK/0",G5="TK/1",G5="K/0"),"KATEGORI A",IF(OR(G5="TK/2",G5="TK/3",G5="K/1",G5="K/2"),"KATEGORI B",IF(OR(G5="K/3"),"KATEGORI C",""))) -> KATEGORI A | I5: Ya | J5: Ya | K5: 2961337 | L5: =455000+325000+650000 -> 1430000 | M5: =+Y5 -> 1637232.6 | N5: =50000*31 -> 1550000 | O5: ='RINCIAN GAJI - GROSS'!W6 -> 7329732.3 | Q5: 9 | R5: =Q5*1.5*1/173*(K5+L5) -> 342676.59 | S5: 25.5 | T5: =S5*2*1/173*(K5+L5) -> 1294556 | V5: =U5*3*1/173*4391337 -> 0 | X5: =W5*4*1/173*4391337 -> 0 | Y5: =R5+T5+V5+X5 -> 1637232.6
A6: =A5+1 -> 5 | B6: ARYABAYA SRIPATI | C6: K262020 | E6: =E5+1 -> 5 | F6: NPWP | G6: TK/0 | H6: =IF(OR(G6="TK/0",G6="TK/1",G6="K/0"),"KATEGORI A",IF(OR(G6="TK/2",G6="TK/3",G6="K/1",G6="K/2"),"KATEGORI B",IF(OR(G6="K/3"),"KATEGORI C",""))) -> KATEGORI A | I6: Ya | J6: Ya | K6: 2961337 | L6: =455000+325000+650000 -> 1430000 | M6: =+Y6 -> 342676.59 | N6: =50000*31 -> 1550000 | O6: ='RINCIAN GAJI - GROSS'!W7 -> 6087154.2 | Q6: 7 | R6: =Q6*1.5*1/173*(K6+L6) -> 266526.23 | S6: 1.5 | T6: =S6*2*1/173*(K6+L6) -> 76150.353 | V6: =U6*3*1/173*4391337 -> 0 | X6: =W6*4*1/173*4391337 -> 0 | Y6: =R6+T6+V6+X6 -> 342676.59
A7: =A6+1 -> 6 | B7: REZA NURHIDAYAT | C7: K262021 | E7: =E6+1 -> 6 | F7: NPWP | G7: TK/0 | H7: =IF(OR(G7="TK/0",G7="TK/1",G7="K/0"),"KATEGORI A",IF(OR(G7="TK/2",G7="TK/3",G7="K/1",G7="K/2"),"KATEGORI B",IF(OR(G7="K/3"),"KATEGORI C",""))) -> KATEGORI A | I7: Ya | J7: Ya | K7: 2961337 | L7: =455000+325000+650000 -> 1430000 | M7: =+Y7 -> 850345.6 | N7: =50000*31 -> 1550000 | O7: ='RINCIAN GAJI - GROSS'!W8 -> 6572197.6 | Q7: 13 | R7: =Q7*1.5*1/173*(K7+L7) -> 494977.29 | S7: 7 | T7: =S7*2*1/173*(K7+L7) -> 355368.31 | V7: =U7*3*1/173*4391337 -> 0 | X7: =W7*4*1/173*4391337 -> 0 | Y7: =R7+T7+V7+X7 -> 850345.6
A8: =A7+1 -> 7 | B8: MUHAMMAD ANSHAR A | C8: K262022 | E8: =E7+1 -> 7 | F8: NPWP | G8: K/1 | H8: =IF(OR(G8="TK/0",G8="TK/1",G8="K/0"),"KATEGORI A",IF(OR(G8="TK/2",G8="TK/3",G8="K/1",G8="K/2"),"KATEGORI B",IF(OR(G8="K/3"),"KATEGORI C",""))) -> KATEGORI B | I8: Ya | J8: Ya | K8: 2961337 | L8: =455000+325000+650000 -> 1430000 | M8: =+Y8 -> 1091488.4 | N8: =50000*31 -> 1550000 | O8: ='RINCIAN GAJI - GROSS'!W9 -> 6846629.8 | Q8: 10 | R8: =Q8*1.5*1/173*(K8+L8) -> 380751.76 | S8: 14 | T8: =S8*2*1/173*(K8+L8) -> 710736.62 | V8: =U8*3*1/173*4391337 -> 0 | X8: =W8*4*1/173*4391337 -> 0 | Y8: =R8+T8+V8+X8 -> 1091488.4
A9: =A8+1 -> 8 | B9: IKA JULITA | C9: K262023 | E9: =E8+1 -> 8 | F9: NPWP | G9: TK/1 | H9: =IF(OR(G9="TK/0",G9="TK/1",G9="K/0"),"KATEGORI A",IF(OR(G9="TK/2",G9="TK/3",G9="K/1",G9="K/2"),"KATEGORI B",IF(OR(G9="K/3"),"KATEGORI C",""))) -> KATEGORI A | I9: Ya | J9: Ya | K9: 2961337 | L9: =455000+325000+650000 -> 1430000 | M9: =+Y9+300000 -> 300000 | N9: =50000*31 -> 1550000 | O9: ='RINCIAN GAJI - GROSS'!W10 -> 6044904.4 | R9: =Q9*1.5*1/173*(K9+L9) -> 0 | T9: =S9*2*1/173*(K9+L9) -> 0 | V9: =U9*3*1/173*4391337 -> 0 | X9: =W9*4*1/173*4391337 -> 0 | Y9: =R9+T9+V9+X9 -> 0
A10: =A9+1 -> 9 | B10: FAJAR SHADIQ HERNANDA | C10: K262024 | E10: =E9+1 -> 9 | F10: NPWP | G10: TK/0 | H10: =IF(OR(G10="TK/0",G10="TK/1",G10="K/0"),"KATEGORI A",IF(OR(G10="TK/2",G10="TK/3",G10="K/1",G10="K/2"),"KATEGORI B",IF(OR(G10="K/3"),"KATEGORI C",""))) -> KATEGORI A | I10: Ya | J10: Ya | K10: 2961337 | L10: =455000+325000+650000 -> 1430000 | M10: =+Y10 -> 342676.59 | N10: =50000*31 -> 1550000 | O10: ='RINCIAN GAJI - GROSS'!W11 -> 6087154.2 | Q10: 7 | R10: =Q10*1.5*1/173*(K10+L10) -> 266526.23 | S10: 1.5 | T10: =S10*2*1/173*(K10+L10) -> 76150.353 | V10: =U10*3*1/173*4391337 -> 0 | X10: =W10*4*1/173*4391337 -> 0 | Y10: =R10+T10+V10+X10 -> 342676.59
A11: =A10+1 -> 10 | B11: BAGUS DWI ARISTA | C11: K262027 | E11: =E10+1 -> 10 | F11: NPWP | G11: TK/0 | H11: =IF(OR(G11="TK/0",G11="TK/1",G11="K/0"),"KATEGORI A",IF(OR(G11="TK/2",G11="TK/3",G11="K/1",G11="K/2"),"KATEGORI B",IF(OR(G11="K/3"),"KATEGORI C",""))) -> KATEGORI A | I11: Ya | J11: Ya | K11: 2961337 | L11: =455000+325000+650000 -> 1430000 | M11: =+Y11 -> 1472240.2 | N11: =50000*31 -> 1550000 | O11: ='RINCIAN GAJI - GROSS'!W12 -> 7167214.7 | Q11: 14 | R11: =Q11*1.5*1/173*(K11+L11) -> 533052.47 | S11: 18.5 | T11: =S11*2*1/173*(K11+L11) -> 939187.68 | V11: =U11*3*1/173*4391337 -> 0 | X11: =W11*4*1/173*4391337 -> 0 | Y11: =R11+T11+V11+X11 -> 1472240.2
A12: =A11+1 -> 11 | B12: SITI AISYAH | C12: K262049 | E12: =E11+1 -> 11 | F12: NPWP | G12: TK/0 | H12: =IF(OR(G12="TK/0",G12="TK/1",G12="K/0"),"KATEGORI A",IF(OR(G12="TK/2",G12="TK/3",G12="K/1",G12="K/2"),"KATEGORI B",IF(OR(G12="K/3"),"KATEGORI C",""))) -> KATEGORI A | I12: Ya | J12: Ya | K12: 2961337 | L12: =455000+325000+650000 -> 1430000 | M12: =+Y12 -> 76150.353 | N12: =50000*31 -> 1550000 | O12: ='RINCIAN GAJI - GROSS'!W13 -> 5838906.8 | Q12: 2 | R12: =Q12*1.5*1/173*(K12+L12) -> 76150.353 | T12: =S12*2*1/173*(K12+L12) -> 0 | V12: =U12*3*1/173*4391337 -> 0 | X12: =W12*4*1/173*4391337 -> 0 | Y12: =R12+T12+V12+X12 -> 76150.353
A13: =A12+1 -> 12 | B13: YUDI BISMANTAKA | C13: K262027 | E13: =E12+1 -> 12 | F13: NPWP | G13: TK/0 | H13: =IF(OR(G13="TK/0",G13="TK/1",G13="K/0"),"KATEGORI A",IF(OR(G13="TK/2",G13="TK/3",G13="K/1",G13="K/2"),"KATEGORI B",IF(OR(G13="K/3"),"KATEGORI C",""))) -> KATEGORI A | I13: Ya | J13: Ya | K13: 2961337 | L13: =455000+325000+650000 -> 1430000 | M13: =+Y13 -> 101533.8 | N13: =50000*31 -> 1550000 | O13: ='RINCIAN GAJI - GROSS'!W14 -> 5864099.8 | Q13: 2 | R13: =Q13*1.5*1/173*(K13+L13) -> 76150.353 | S13: 0.5 | T13: =S13*2*1/173*(K13+L13) -> 25383.451 | V13: =U13*3*1/173*4391337 -> 0 | X13: =W13*4*1/173*4391337 -> 0 | Y13: =R13+T13+V13+X13 -> 101533.8
A14: =A13+1 -> 13 | B14: WARDY | C14: K262056 | E14: =E13+1 -> 13 | F14: NPWP | G14: TK/0 | H14: =IF(OR(G14="TK/0",G14="TK/1",G14="K/0"),"KATEGORI A",IF(OR(G14="TK/2",G14="TK/3",G14="K/1",G14="K/2"),"KATEGORI B",IF(OR(G14="K/3"),"KATEGORI C",""))) -> KATEGORI A | I14: Ya | J14: Ya | K14: 2961337 | L14: =455000+325000+650000 -> 1430000 | M14: =+Y14 -> 698044.9 | N14: =50000*31 -> 1550000 | O14: ='RINCIAN GAJI - GROSS'!W15 -> 6421800.6 | Q14: 9 | R14: =Q14*1.5*1/173*(K14+L14) -> 342676.59 | S14: 7 | T14: =S14*2*1/173*(K14+L14) -> 355368.31 | V14: =U14*3*1/173*4391337 -> 0 | X14: =W14*4*1/173*4391337 -> 0 | Y14: =R14+T14+V14+X14 -> 698044.9
A15: =A14+1 -> 14 | B15: HANDRI PANGESTU | C15: K262057 | E15: =E14+1 -> 14 | F15: NPWP | G15: TK/0 | H15: =IF(OR(G15="TK/0",G15="TK/1",G15="K/0"),"KATEGORI A",IF(OR(G15="TK/2",G15="TK/3",G15="K/1",G15="K/2"),"KATEGORI B",IF(OR(G15="K/3"),"KATEGORI C",""))) -> KATEGORI A | I15: Ya | J15: Ya | K15: 2961337 | L15: =455000+325000+650000 -> 1430000 | M15: =+Y15 -> 418826.94 | N15: =50000*31 -> 1550000 | O15: ='RINCIAN GAJI - GROSS'!W16 -> 6162543.1 | Q15: 3 | R15: =Q15*1.5*1/173*(K15+L15) -> 114225.53 | S15: 6 | T15: =S15*2*1/173*(K15+L15) -> 304601.41 | V15: =U15*3*1/173*4391337 -> 0 | X15: =W15*4*1/173*4391337 -> 0 | Y15: =R15+T15+V15+X15 -> 418826.94
A16: =A15+1 -> 15 | B16: MUHAMMAD BAYU ARDIANTO | C16: K262058 | E16: =E15+1 -> 15 | F16: NPWP | G16: TK/0 | H16: =IF(OR(G16="TK/0",G16="TK/1",G16="K/0"),"KATEGORI A",IF(OR(G16="TK/2",G16="TK/3",G16="K/1",G16="K/2"),"KATEGORI B",IF(OR(G16="K/3"),"KATEGORI C",""))) -> KATEGORI A | I16: Ya | J16: Ya | K16: 2961337 | L16: =455000+325000+650000 -> 1430000 | M16: =+Y16 -> 101533.8 | N16: =50000*31 -> 1550000 | O16: ='RINCIAN GAJI - GROSS'!W17 -> 5864099.8 | Q16: 2 | R16: =Q16*1.5*1/173*(K16+L16) -> 76150.353 | S16: 0.5 | T16: =S16*2*1/173*(K16+L16) -> 25383.451 | V16: =U16*3*1/173*4391337 -> 0 | X16: =W16*4*1/173*4391337 -> 0 | Y16: =R16+T16+V16+X16 -> 101533.8
A17: =A16+1 -> 16 | B17: MUHAMMAD ZETYO D.H | C17: K262060 | D17: PLKS. LINGK & MUK | E17: =E16+1 -> 16 | F17: NPWP | G17: TK/0 | H17: =IF(OR(G17="TK/0",G17="TK/1",G17="K/0"),"KATEGORI A",IF(OR(G17="TK/2",G17="TK/3",G17="K/1",G17="K/2"),"KATEGORI B",IF(OR(G17="K/3"),"KATEGORI C",""))) -> KATEGORI A | I17: Ya | J17: Ya | K17: 2961337 | L17: =455000+325000+650000 -> 1430000 | M17: =+Y17 -> 266526.23 | N17: =50000*31 -> 1550000 | O17: ='RINCIAN GAJI - GROSS'!W18 -> 6011765.4 | Q17: 1 | R17: =Q17*1.5*1/173*(K17+L17) -> 38075.176 | S17: 4.5 | T17: =S17*2*1/173*(K17+L17) -> 228451.06 | V17: =U17*3*1/173*4391337 -> 0 | X17: =W17*4*1/173*4391337 -> 0 | Y17: =R17+T17+V17+X17 -> 266526.23
A18: =A17+1 -> 17 | B18: MUHAMMAD HIDAYATULLAH | C18: K262061 | D18: PLKS PNM & PML | E18: =E17+1 -> 17 | F18: NPWP | G18: TK/0 | H18: =IF(OR(G18="TK/0",G18="TK/1",G18="K/0"),"KATEGORI A",IF(OR(G18="TK/2",G18="TK/3",G18="K/1",G18="K/2"),"KATEGORI B",IF(OR(G18="K/3"),"KATEGORI C",""))) -> KATEGORI A | I18: Ya | J18: Ya | K18: 2961337 | L18: =455000+325000+650000 -> 1430000 | M18: =+Y18 -> 38075.176 | N18: =50000*31 -> 1550000 | O18: ='RINCIAN GAJI - GROSS'!W19 -> 5801117.1 | Q18: 1 | R18: =Q18*1.5*1/173*(K18+L18) -> 38075.176 | T18: =S18*2*1/173*(K18+L18) -> 0 | V18: =U18*3*1/173*4391337 -> 0 | X18: =W18*4*1/173*4391337 -> 0 | Y18: =R18+T18+V18+X18 -> 38075.176
A19: =A18+1 -> 18 | B19: ALYA JUNIANTI PRATIWI | C19: K262062 | D19: PLKS SDM DAN UMUM | E19: =E18+1 -> 18 | F19: NPWP | G19: TK/0 | H19: =IF(OR(G19="TK/0",G19="TK/1",G19="K/0"),"KATEGORI A",IF(OR(G19="TK/2",G19="TK/3",G19="K/1",G19="K/2"),"KATEGORI B",IF(OR(G19="K/3"),"KATEGORI C",""))) -> KATEGORI A | I19: Ya | J19: Ya | K19: 2961337 | L19: =455000+325000+650000 -> 1430000 | M19: =+Y19 -> 63458.627 | N19: =50000*31 -> 1550000 | O19: ='RINCIAN GAJI - GROSS'!W20 -> 5826310.2 | Q19: 1 | R19: =Q19*1.5*1/173*(K19+L19) -> 38075.176 | S19: 0.5 | T19: =S19*2*1/173*(K19+L19) -> 25383.451 | V19: =U19*3*1/173*4391337 -> 0 | X19: =W19*4*1/173*4391337 -> 0 | Y19: =R19+T19+V19+X19 -> 63458.627
A20: =A19+1 -> 19 | B20: MUAMMAR AKRAM | C20: K262065 | D20: PLKS PERENCANAAN | E20: =E19+1 -> 19 | F20: NPWP | G20: TK/0 | H20: =IF(OR(G20="TK/0",G20="TK/1",G20="K/0"),"KATEGORI A",IF(OR(G20="TK/2",G20="TK/3",G20="K/1",G20="K/2"),"KATEGORI B",IF(OR(G20="K/3"),"KATEGORI C",""))) -> KATEGORI A | I20: Ya | J20: Ya | K20: 2961337 | L20: =455000+325000+650000 -> 1430000 | M20: =+Y20 -> 1053413.2 | N20: =50000*31 -> 1550000 | O20: ='RINCIAN GAJI - GROSS'!W21 -> 6772726.8 | Q20: 9 | R20: =Q20*1.5*1/173*(K20+L20) -> 342676.59 | S20: 14 | T20: =S20*2*1/173*(K20+L20) -> 710736.62 | V20: =U20*3*1/173*4391337 -> 0 | X20: =W20*4*1/173*4391337 -> 0 | Y20: =R20+T20+V20+X20 -> 1053413.2
A21: =A20+1 -> 20 | B21: DARMAWAN SYAH | C21: K262066 | D21: OP EXCA MUK | E21: =E20+1 -> 20 | F21: NPWP | G21: K/2 | H21: =IF(OR(G21="TK/0",G21="TK/1",G21="K/0"),"KATEGORI A",IF(OR(G21="TK/2",G21="TK/3",G21="K/1",G21="K/2"),"KATEGORI B",IF(OR(G21="K/3"),"KATEGORI C",""))) -> KATEGORI B | I21: Ya | J21: Ya | K21: 2500000 | M21: =+Y21+4701000 -> 4701000 | N21: 600000 | O21: ='RINCIAN GAJI - GROSS'!W22 -> 7588970.8 | R21: =Q21*1.5*1/173*(K21+L21) -> 0 | T21: =S21*2*1/173*(K21+L21) -> 0 | V21: =U21*3*1/173*4391337 -> 0 | X21: =W21*4*1/173*4391337 -> 0 | Y21: =R21+T21+V21+X21 -> 0
A22: =A21+1 -> 21 | B22: MARIYAM | C22: K262072 | D22: JURMAS | E22: =E21+1 -> 21 | F22: NPWP | G22: TK/0 | H22: =IF(OR(G22="TK/0",G22="TK/1",G22="K/0"),"KATEGORI A",IF(OR(G22="TK/2",G22="TK/3",G22="K/1",G22="K/2"),"KATEGORI B",IF(OR(G22="K/3"),"KATEGORI C",""))) -> KATEGORI A | I22: Ya | J22: Ya | K22: 2961337 | L22: =455000+325000+650000 -> 1430000 | M22: 300000 | N22: =50000*24 -> 1200000 | O22: ='RINCIAN GAJI - GROSS'!W23 -> 5713702.5 | R22: =Q22*1.5*1/173*(K22+L22) -> 0 | T22: =S22*2*1/173*(K22+L22) -> 0 | V22: =U22*3*1/173*4391337 -> 0 | X22: =W22*4*1/173*4391337 -> 0 | Y22: =R22+T22+V22+X22 -> 0
A23: =A22+1 -> 22 | B23: ACHMAD RENALDI | C23: K262076 | D23: PLKS UMUM DRIVER MUK | E23: =E22+1 -> 22 | F23: NPWP | G23: TK/0 | H23: =IF(OR(G23="TK/0",G23="TK/1",G23="K/0"),"KATEGORI A",IF(OR(G23="TK/2",G23="TK/3",G23="K/1",G23="K/2"),"KATEGORI B",IF(OR(G23="K/3"),"KATEGORI C",""))) -> KATEGORI A | I23: Ya | J23: Ya | K23: 2961337 | L23: =455000+325000+650000 -> 1430000 | M23: =+Y23 -> 2614495.4 | N23: =50000*18 -> 900000 | O23: ='RINCIAN GAJI - GROSS'!W24 -> 7652086.2 | Q23: 6 | R23: =Q23*1.5*1/173*(K23+L23) -> 228451.06 | S23: 47 | T23: =S23*2*1/173*(K23+L23) -> 2386044.4 | V23: =U23*3*1/173*4391337 -> 0 | X23: =W23*4*1/173*4391337 -> 0 | Y23: =R23+T23+V23+X23 -> 2614495.4
A24: =A23+1 -> 23 | B24: ARIF GUNAWAN | C24: K262078 | D24: PLKS PAMHUTSOS | E24: =E23+1 -> 23 | F24: NPWP | G24: K/1 | H24: =IF(OR(G24="TK/0",G24="TK/1",G24="K/0"),"KATEGORI A",IF(OR(G24="TK/2",G24="TK/3",G24="K/1",G24="K/2"),"KATEGORI B",IF(OR(G24="K/3"),"KATEGORI C",""))) -> KATEGORI B | I24: Ya | J24: Ya | K24: 2961337 | L24: =455000+325000+650000 -> 1430000 | M24: =+Y24 -> 126917.25 | N24: =50000*16 -> 800000 | O24: ='RINCIAN GAJI - GROSS'!W25 -> 5186514.1 | Q24: 2 | R24: =Q24*1.5*1/173*(K24+L24) -> 76150.353 | S24: 1 | T24: =S24*2*1/173*(K24+L24) -> 50766.902 | V24: =U24*3*1/173*4391337 -> 0 | X24: =W24*4*1/173*4391337 -> 0 | Y24: =R24+T24+V24+X24 -> 126917.25
O25: ='RINCIAN GAJI - GROSS'!W26 -> 0
O26: ='RINCIAN GAJI - GROSS'!W27 -> 0 | T26: =S26*2*1/173*(K26+L26) -> 0 | V26: =U26*3*1/173*4391337 -> 0 | X26: =W26*4*1/173*4391337 -> 0 | Y26: =R26+T26+V26+X26 -> 0
O27: ='RINCIAN GAJI - GROSS'!W28 -> 0 | T27: =S27*2*1/173*(K27+L27) -> 0 | V27: =U27*3*1/173*4391337 -> 0 | X27: =W27*4*1/173*4391337 -> 0 | Y27: =R27+T27+V27+X27 -> 0

Sheet BPJS TK
A1: No | B1: Nama | C1: Upah yang Didaftarkan | D1: Iuran JKK | E1: Iuran JKM | F1: Iuran Jaminan Hari Tua | H1: Iuran Jaminan Pensiun | J1: Total
F2: Pemberi Kerja | G2: Tenaga Kerja | H2: Pemberi Kerja | I2: Tenaga Kerja
A3: =IF('TENAGA KERJA'!A2=0,"",'TENAGA KERJA'!A2) -> 1 | B3: =IF('TENAGA KERJA'!B2=0,"",'TENAGA KERJA'!B2) -> ABDUL HALIM | C3: =IF('TENAGA KERJA'!I2="Tidak",0,('TENAGA KERJA'!K2+'TENAGA KERJA'!L2)) -> 4391337 | D3: =C3*SETTING!$C$10 -> 39082.899 | E3: =C3*SETTING!$C$11 -> 13174.011 | F3: =C3*SETTING!$C$12 -> 162479.47 | G3: =C3*SETTING!$C$13 -> 87826.74 | J3: =SUM(D3:I3) -> 302563.12
A4: =IF('TENAGA KERJA'!A3=0,"",'TENAGA KERJA'!A3) -> 2 | B4: =IF('TENAGA KERJA'!B3=0,"",'TENAGA KERJA'!B3) -> SRI ASLINDA | C4: =IF('TENAGA KERJA'!I3="Tidak",0,('TENAGA KERJA'!K3+'TENAGA KERJA'!L3)) -> 4391337 | D4: =C4*SETTING!$C$10 -> 39082.899 | E4: =C4*SETTING!$C$11 -> 13174.011 | F4: =C4*SETTING!$C$12 -> 162479.47 | G4: =C4*SETTING!$C$13 -> 87826.74 | J4: =SUM(D4:I4) -> 302563.12
A5: =IF('TENAGA KERJA'!A4=0,"",'TENAGA KERJA'!A4) -> 3 | B5: =IF('TENAGA KERJA'!B4=0,"",'TENAGA KERJA'!B4) -> RAFLY RAHMADAN GOBEL | C5: =IF('TENAGA KERJA'!I4="Tidak",0,('TENAGA KERJA'!K4+'TENAGA KERJA'!L4)) -> 4391337 | D5: =C5*SETTING!$C$10 -> 39082.899 | E5: =C5*SETTING!$C$11 -> 13174.011 | F5: =C5*SETTING!$C$12 -> 162479.47 | G5: =C5*SETTING!$C$13 -> 87826.74 | J5: =SUM(D5:I5) -> 302563.12
A6: =IF('TENAGA KERJA'!A5=0,"",'TENAGA KERJA'!A5) -> 4 | B6: =IF('TENAGA KERJA'!B5=0,"",'TENAGA KERJA'!B5) -> RAHMAT HIDAYAT | C6: =IF('TENAGA KERJA'!I5="Tidak",0,('TENAGA KERJA'!K5+'TENAGA KERJA'!L5)) -> 4391337 | D6: =C6*SETTING!$C$10 -> 39082.899 | E6: =C6*SETTING!$C$11 -> 13174.011 | F6: =C6*SETTING!$C$12 -> 162479.47 | G6: =C6*SETTING!$C$13 -> 87826.74 | J6: =SUM(D6:I6) -> 302563.12
A7: =IF('TENAGA KERJA'!A6=0,"",'TENAGA KERJA'!A6) -> 5 | B7: =IF('TENAGA KERJA'!B6=0,"",'TENAGA KERJA'!B6) -> ARYABAYA SRIPATI | C7: =IF('TENAGA KERJA'!I6="Tidak",0,('TENAGA KERJA'!K6+'TENAGA KERJA'!L6)) -> 4391337 | D7: =C7*SETTING!$C$10 -> 39082.899 | E7: =C7*SETTING!$C$11 -> 13174.011 | F7: =C7*SETTING!$C$12 -> 162479.47 | G7: =C7*SETTING!$C$13 -> 87826.74 | J7: =SUM(D7:I7) -> 302563.12
A8: =IF('TENAGA KERJA'!A7=0,"",'TENAGA KERJA'!A7) -> 6 | B8: =IF('TENAGA KERJA'!B7=0,"",'TENAGA KERJA'!B7) -> REZA NURHIDAYAT | C8: =IF('TENAGA KERJA'!I7="Tidak",0,('TENAGA KERJA'!K7+'TENAGA KERJA'!L7)) -> 4391337 | D8: =C8*SETTING!$C$10 -> 39082.899 | E8: =C8*SETTING!$C$11 -> 13174.011 | F8: =C8*SETTING!$C$12 -> 162479.47 | G8: =C8*SETTING!$C$13 -> 87826.74 | J8: =SUM(D8:I8) -> 302563.12
A9: =IF('TENAGA KERJA'!A8=0,"",'TENAGA KERJA'!A8) -> 7 | B9: =IF('TENAGA KERJA'!B8=0,"",'TENAGA KERJA'!B8) -> MUHAMMAD ANSHAR A | C9: =IF('TENAGA KERJA'!I8="Tidak",0,('TENAGA KERJA'!K8+'TENAGA KERJA'!L8)) -> 4391337 | D9: =C9*SETTING!$C$10 -> 39082.899 | E9: =C9*SETTING!$C$11 -> 13174.011 | F9: =C9*SETTING!$C$12 -> 162479.47 | G9: =C9*SETTING!$C$13 -> 87826.74 | J9: =SUM(D9:I9) -> 302563.12
A10: =IF('TENAGA KERJA'!A9=0,"",'TENAGA KERJA'!A9) -> 8 | B10: =IF('TENAGA KERJA'!B9=0,"",'TENAGA KERJA'!B9) -> IKA JULITA | C10: =IF('TENAGA KERJA'!I9="Tidak",0,('TENAGA KERJA'!K9+'TENAGA KERJA'!L9)) -> 4391337 | D10: =C10*SETTING!$C$10 -> 39082.899 | E10: =C10*SETTING!$C$11 -> 13174.011 | F10: =C10*SETTING!$C$12 -> 162479.47 | G10: =C10*SETTING!$C$13 -> 87826.74 | J10: =SUM(D10:I10) -> 302563.12
A11: =IF('TENAGA KERJA'!A10=0,"",'TENAGA KERJA'!A10) -> 9 | B11: =IF('TENAGA KERJA'!B10=0,"",'TENAGA KERJA'!B10) -> FAJAR SHADIQ HERNANDA | C11: =IF('TENAGA KERJA'!I10="Tidak",0,('TENAGA KERJA'!K10+'TENAGA KERJA'!L10)) -> 4391337 | D11: =C11*SETTING!$C$10 -> 39082.899 | E11: =C11*SETTING!$C$11 -> 13174.011 | F11: =C11*SETTING!$C$12 -> 162479.47 | G11: =C11*SETTING!$C$13 -> 87826.74 | J11: =SUM(D11:I11) -> 302563.12
A12: =IF('TENAGA KERJA'!A11=0,"",'TENAGA KERJA'!A11) -> 10 | B12: =IF('TENAGA KERJA'!B11=0,"",'TENAGA KERJA'!B11) -> BAGUS DWI ARISTA | C12: =IF('TENAGA KERJA'!I11="Tidak",0,('TENAGA KERJA'!K11+'TENAGA KERJA'!L11)) -> 4391337 | D12: =C12*SETTING!$C$10 -> 39082.899 | E12: =C12*SETTING!$C$11 -> 13174.011 | F12: =C12*SETTING!$C$12 -> 162479.47 | G12: =C12*SETTING!$C$13 -> 87826.74 | J12: =SUM(D12:I12) -> 302563.12
A13: =IF('TENAGA KERJA'!A12=0,"",'TENAGA KERJA'!A12) -> 11 | B13: =IF('TENAGA KERJA'!B12=0,"",'TENAGA KERJA'!B12) -> SITI AISYAH | C13: =IF('TENAGA KERJA'!I12="Tidak",0,('TENAGA KERJA'!K12+'TENAGA KERJA'!L12)) -> 4391337 | D13: =C13*SETTING!$C$10 -> 39082.899 | E13: =C13*SETTING!$C$11 -> 13174.011 | F13: =C13*SETTING!$C$12 -> 162479.47 | G13: =C13*SETTING!$C$13 -> 87826.74 | J13: =SUM(D13:I13) -> 302563.12
A14: =IF('TENAGA KERJA'!A13=0,"",'TENAGA KERJA'!A13) -> 12 | B14: =IF('TENAGA KERJA'!B13=0,"",'TENAGA KERJA'!B13) -> YUDI BISMANTAKA | C14: =IF('TENAGA KERJA'!I13="Tidak",0,('TENAGA KERJA'!K13+'TENAGA KERJA'!L13)) -> 4391337 | D14: =C14*SETTING!$C$10 -> 39082.899 | E14: =C14*SETTING!$C$11 -> 13174.011 | F14: =C14*SETTING!$C$12 -> 162479.47 | G14: =C14*SETTING!$C$13 -> 87826.74 | J14: =SUM(D14:I14) -> 302563.12
... A21: =IF('TENAGA KERJA'!A20=0,"",'TENAGA KERJA'!A20) -> 19 | B21: =IF('TENAGA KERJA'!B20=0,"",'TENAGA KERJA'!B20) -> MUAMMAR AKRAM | C21: =IF('TENAGA KERJA'!I20="Tidak",0,('TENAGA KERJA'!K20+'TENAGA KERJA'!L20)) -> 4391337 | D21: =C21*SETTING!$C$10 -> 39082.899 | E21: =C21*SETTING!$C$11 -> 13174.011 | F21: =C21*SETTING!$C$12 -> 162479.47 | G21: =C21*SETTING!$C$13 -> 87826.74 | J21: =SUM(D21:I21) -> 302563.12
A22: =IF('TENAGA KERJA'!A21=0,"",'TENAGA KERJA'!A21) -> 20 | B22: =IF('TENAGA KERJA'!B21=0,"",'TENAGA KERJA'!B21) -> DARMAWAN SYAH | C22: =IF('TENAGA KERJA'!I21="Tidak",0,('TENAGA KERJA'!K21+'TENAGA KERJA'!L21))+1891337 -> 4391337 | D22: =C22*SETTING!$C$10 -> 39082.899 | E22: =C22*SETTING!$C$11 -> 13174.011 | F22: =C22*SETTING!$C$12 -> 162479.47 | G22: =C22*SETTING!$C$13 -> 87826.74 | J22: =SUM(D22:I22) -> 302563.12
A23: =IF('TENAGA KERJA'!A22=0,"",'TENAGA KERJA'!A22) -> 21 | B23: =IF('TENAGA KERJA'!B22=0,"",'TENAGA KERJA'!B22) -> MARIYAM | C23: =IF('TENAGA KERJA'!I22="Tidak",0,('TENAGA KERJA'!K22+'TENAGA KERJA'!L22)) -> 4391337 | D23: =C23*SETTING!$C$10 -> 39082.899 | E23: =C23*SETTING!$C$11 -> 13174.011 | F23: =C23*SETTING!$C$12 -> 162479.47 | G23: =C23*SETTING!$C$13 -> 87826.74 | J23: =SUM(D23:I23) -> 302563.12
A24: =IF('TENAGA KERJA'!A23=0,"",'TENAGA KERJA'!A23) -> 22 | B24: =IF('TENAGA KERJA'!B23=0,"",'TENAGA KERJA'!B23) -> ACHMAD RENALDI | C24: =IF('TENAGA KERJA'!I23="Tidak",0,('TENAGA KERJA'!K23+'TENAGA KERJA'!L23)) -> 4391337 | D24: =C24*SETTING!$C$10 -> 39082.899 | E24: =C24*SETTING!$C$11 -> 13174.011 | F24: =C24*SETTING!$C$12 -> 162479.47 | G24: =C24*SETTING!$C$13 -> 87826.74 | J24: =SUM(D24:I24) -> 302563.12
A25: =IF('TENAGA KERJA'!A24=0,"",'TENAGA KERJA'!A24) -> 23 | B25: =IF('TENAGA KERJA'!B24=0,"",'TENAGA KERJA'!B24) -> ARIF GUNAWAN | C25: =IF('TENAGA KERJA'!I24="Tidak",0,('TENAGA KERJA'!K24+'TENAGA KERJA'!L24)) -> 4391337 | D25: =C25*SETTING!$C$10 -> 39082.899 | E25: =C25*SETTING!$C$11 -> 13174.011 | F25: =C25*SETTING!$C$12 -> 162479.47 | G25: =C25*SETTING!$C$13 -> 87826.74 | J25: =SUM(D25:I25) -> 302563.12
A26: =IF('TENAGA KERJA'!A25=0,"",'TENAGA KERJA'!A25) | B26: =IF('TENAGA KERJA'!B25=0,"",'TENAGA KERJA'!B25) | C26: =IF('TENAGA KERJA'!I25="Tidak",0,('TENAGA KERJA'!K25+'TENAGA KERJA'!L25)) -> 0 | D26: =C26*SETTING!$C$10 -> 0 | E26: =C26*SETTING!$C$11 -> 0 | F26: =C26*SETTING!$C$12 -> 0 | G26: =C26*SETTING!$C$13 -> 0 | J26: =SUM(D26:I26) -> 0
A27: =IF('TENAGA KERJA'!A26=0,"",'TENAGA KERJA'!A26) | B27: =IF('TENAGA KERJA'!B26=0,"",'TENAGA KERJA'!B26) | C27: =IF('TENAGA KERJA'!I26="Tidak",0,('TENAGA KERJA'!K26+'TENAGA KERJA'!L26)) -> 0 | D27: =C27*SETTING!$C$10 -> 0 | E27: =C27*SETTING!$C$11 -> 0 | F27: =C27*SETTING!$C$12 -> 0 | G27: =C27*SETTING!$C$13 -> 0 | J27: =SUM(D27:I27) -> 0
A28: =IF('TENAGA KERJA'!A27=0,"",'TENAGA KERJA'!A27) | B28: =IF('TENAGA KERJA'!B27=0,"",'TENAGA KERJA'!B27) | C28: =IF('TENAGA KERJA'!I27="Tidak",0,('TENAGA KERJA'!K27+'TENAGA KERJA'!L27)) -> 0 | D28: =C28*SETTING!$C$10 -> 0 | E28: =C28*SETTING!$C$11 -> 0 | F28: =C28*SETTING!$C$12 -> 0 | G28: =C28*SETTING!$C$13 -> 0 | J28: =SUM(D28:I28) -> 0
A29: =IF('TENAGA KERJA'!A28=0,"",'TENAGA KERJA'!A28) | B29: =IF('TENAGA KERJA'!B28=0,"",'TENAGA KERJA'!B28) | C29: =IF('TENAGA KERJA'!I28="Tidak",0,('TENAGA KERJA'!K28+'TENAGA KERJA'!L28)) -> 0 | D29: =C29*SETTING!$C$10 -> 0 | E29: =C29*SETTING!$C$11 -> 0 | F29: =C29*SETTING!$C$12 -> 0 | G29: =C29*SETTING!$C$13 -> 0 | J29: =SUM(D29:I29) -> 0
A30: =IF('TENAGA KERJA'!A29=0,"",'TENAGA KERJA'!A29) | B30: =IF('TENAGA KERJA'!B29=0,"",'TENAGA KERJA'!B29) | C30: =IF('TENAGA KERJA'!I29="Tidak",0,('TENAGA KERJA'!K29+'TENAGA KERJA'!L29)) -> 0 | D30: =C30*SETTING!$C$10 -> 0 | E30: =C30*SETTING!$C$11 -> 0 | F30: =C30*SETTING!$C$12 -> 0 | G30: =C30*SETTING!$C$13 -> 0 | J30: =SUM(D30:I30) -> 0
A31: =IF('TENAGA KERJA'!A30=0,"",'TENAGA KERJA'!A30) | B31: =IF('TENAGA KERJA'!B30=0,"",'TENAGA KERJA'!B30) | C31: =IF('TENAGA KERJA'!I30="Tidak",0,('TENAGA KERJA'!K30+'TENAGA KERJA'!L30)) -> 0 | D31: =C31*SETTING!$C$10 -> 0 | E31: =C31*SETTING!$C$11 -> 0 | F31: =C31*SETTING!$C$12 -> 0 | G31: =C31*SETTING!$C$13 -> 0 | J31: =SUM(D31:I31) -> 0
A32: =IF('TENAGA KERJA'!A31=0,"",'TENAGA KERJA'!A31) | B32: =IF('TENAGA KERJA'!B31=0,"",'TENAGA KERJA'!B31) | C32: =IF('TENAGA KERJA'!I31="Tidak",0,('TENAGA KERJA'!K31+'TENAGA KERJA'!L31)) -> 0 | D32: =C32*SETTING!$C$10 -> 0 | E32: =C32*SETTING!$C$11 -> 0 | F32: =C32*SETTING!$C$12 -> 0 | G32: =C32*SETTING!$C$13 -> 0 | J32: =SUM(D32:I32) -> 0
A33: =IF('TENAGA KERJA'!A32=0,"",'TENAGA KERJA'!A32) | B33: =IF('TENAGA KERJA'!B32=0,"",'TENAGA KERJA'!B32) | C33: =IF('TENAGA KERJA'!I32="Tidak",0,('TENAGA KERJA'!K32+'TENAGA KERJA'!L32)) -> 0 | D33: =C33*SETTING!$C$10 -> 0 | E33: =C33*SETTING!$C$11 -> 0 | F33: =C33*SETTING!$C$12 -> 0 | G33: =C33*SETTING!$C$13 -> 0 | J33: =SUM(D33:I33) -> 0
A34: =IF('TENAGA KERJA'!A33=0,"",'TENAGA KERJA'!A33) | B34: =IF('TENAGA KERJA'!B33=0,"",'TENAGA KERJA'!B33) | C34: =IF('TENAGA KERJA'!I33="Tidak",0,('TENAGA KERJA'!K33+'TENAGA KERJA'!L33)) -> 0 | D34: =C34*SETTING!$C$10 -> 0 | E34: =C34*SETTING!$C$11 -> 0 | F34: =C34*SETTING!$C$12 -> 0 | G34: =C34*SETTING!$C$13 -> 0 | J34: =SUM(D34:I34) -> 0
... A39: =IF('TENAGA KERJA'!A38=0,"",'TENAGA KERJA'!A38) | B39: =IF('TENAGA KERJA'!B38=0,"",'TENAGA KERJA'!B38) | C39: =IF('TENAGA KERJA'!I38="Tidak",0,('TENAGA KERJA'!K38+'TENAGA KERJA'!L38)) -> 0 | D39: =C39*SETTING!$C$10 -> 0 | E39: =C39*SETTING!$C$11 -> 0 | F39: =C39*SETTING!$C$12 -> 0 | G39: =C39*SETTING!$C$13 -> 0 | J39: =SUM(D39:I39) -> 0
A40: =IF('TENAGA KERJA'!A39=0,"",'TENAGA KERJA'!A39) | B40: =IF('TENAGA KERJA'!B39=0,"",'TENAGA KERJA'!B39) | C40: =IF('TENAGA KERJA'!I39="Tidak",0,('TENAGA KERJA'!K39+'TENAGA KERJA'!L39)) -> 0 | D40: =C40*SETTING!$C$10 -> 0 | E40: =C40*SETTING!$C$11 -> 0 | F40: =C40*SETTING!$C$12 -> 0 | G40: =C40*SETTING!$C$13 -> 0 | J40: =SUM(D40:I40) -> 0 | K40: =C38-1796456 -> -1796456
A41: =IF('TENAGA KERJA'!A40=0,"",'TENAGA KERJA'!A40) | B41: =IF('TENAGA KERJA'!B40=0,"",'TENAGA KERJA'!B40) | C41: =IF('TENAGA KERJA'!I40="Tidak",0,('TENAGA KERJA'!K40+'TENAGA KERJA'!L40)) -> 0 | D41: =C41*SETTING!$C$10 -> 0 | E41: =C41*SETTING!$C$11 -> 0 | F41: =C41*SETTING!$C$12 -> 0 | G41: =C41*SETTING!$C$13 -> 0 | J41: =SUM(D41:I41) -> 0
A42: =IF('TENAGA KERJA'!A41=0,"",'TENAGA KERJA'!A41) | B42: =IF('TENAGA KERJA'!B41=0,"",'TENAGA KERJA'!B41) | C42: =IF('TENAGA KERJA'!I41="Tidak",0,('TENAGA KERJA'!K41+'TENAGA KERJA'!L41)) -> 0 | D42: =C42*SETTING!$C$10 -> 0 | E42: =C42*SETTING!$C$11 -> 0 | F42: =C42*SETTING!$C$12 -> 0 | G42: =C42*SETTING!$C$13 -> 0 | J42: =SUM(D42:I42) -> 0
A43: =IF('TENAGA KERJA'!A42=0,"",'TENAGA KERJA'!A42) | B43: =IF('TENAGA KERJA'!B42=0,"",'TENAGA KERJA'!B42) | C43: =IF('TENAGA KERJA'!I42="Tidak",0,('TENAGA KERJA'!K42+'TENAGA KERJA'!L42)) -> 0 | D43: =C43*SETTING!$C$10 -> 0 | E43: =C43*SETTING!$C$11 -> 0 | F43: =C43*SETTING!$C$12 -> 0 | G43: =C43*SETTING!$C$13 -> 0 | J43: =SUM(D43:I43) -> 0
A44: =IF('TENAGA KERJA'!A43=0,"",'TENAGA KERJA'!A43) | B44: =IF('TENAGA KERJA'!B43=0,"",'TENAGA KERJA'!B43) | C44: =IF('TENAGA KERJA'!I43="Tidak",0,('TENAGA KERJA'!K43+'TENAGA KERJA'!L43)) -> 0 | D44: =C44*SETTING!$C$10 -> 0 | E44: =C44*SETTING!$C$11 -> 0 | F44: =C44*SETTING!$C$12 -> 0 | G44: =C44*SETTING!$C$13 -> 0 | J44: =SUM(D44:I44) -> 0
A45: =IF('TENAGA KERJA'!A44=0,"",'TENAGA KERJA'!A44) | B45: =IF('TENAGA KERJA'!B44=0,"",'TENAGA KERJA'!B44) | C45: =IF('TENAGA KERJA'!I44="Tidak",0,('TENAGA KERJA'!K44+'TENAGA KERJA'!L44)) -> 0 | D45: =C45*SETTING!$C$10 -> 0 | E45: =C45*SETTING!$C$11 -> 0 | F45: =C45*SETTING!$C$12 -> 0 | G45: =C45*SETTING!$C$13 -> 0 | J45: =SUM(D45:I45) -> 0
A46: =IF('TENAGA KERJA'!A45=0,"",'TENAGA KERJA'!A45) | B46: =IF('TENAGA KERJA'!B45=0,"",'TENAGA KERJA'!B45) | C46: =IF('TENAGA KERJA'!I45="Tidak",0,('TENAGA KERJA'!K45+'TENAGA KERJA'!L45)) -> 0 | D46: =C46*SETTING!$C$10 -> 0 | E46: =C46*SETTING!$C$11 -> 0 | F46: =C46*SETTING!$C$12 -> 0 | G46: =C46*SETTING!$C$13 -> 0 | J46: =SUM(D46:I46) -> 0
A47: =IF('TENAGA KERJA'!A46=0,"",'TENAGA KERJA'!A46) | B47: =IF('TENAGA KERJA'!B46=0,"",'TENAGA KERJA'!B46) | C47: =IF('TENAGA KERJA'!I46="Tidak",0,('TENAGA KERJA'!K46+'TENAGA KERJA'!L46)) -> 0 | D47: =C47*SETTING!$C$10 -> 0 | E47: =C47*SETTING!$C$11 -> 0 | F47: =C47*SETTING!$C$12 -> 0 | G47: =C47*SETTING!$C$13 -> 0 | J47: =SUM(D47:I47) -> 0
A48: =IF('TENAGA KERJA'!A47=0,"",'TENAGA KERJA'!A47) | B48: =IF('TENAGA KERJA'!B47=0,"",'TENAGA KERJA'!B47) | C48: =IF('TENAGA KERJA'!I47="Tidak",0,('TENAGA KERJA'!K47+'TENAGA KERJA'!L47)) -> 0 | D48: =C48*SETTING!$C$10 -> 0 | E48: =C48*SETTING!$C$11 -> 0 | F48: =C48*SETTING!$C$12 -> 0 | G48: =C48*SETTING!$C$13 -> 0 | J48: =SUM(D48:I48) -> 0
A49: =IF('TENAGA KERJA'!A48=0,"",'TENAGA KERJA'!A48) | B49: =IF('TENAGA KERJA'!B48=0,"",'TENAGA KERJA'!B48) | C49: =IF('TENAGA KERJA'!I48="Tidak",0,('TENAGA KERJA'!K48+'TENAGA KERJA'!L48)) -> 0 | D49: =C49*SETTING!$C$10 -> 0 | E49: =C49*SETTING!$C$11 -> 0 | F49: =C49*SETTING!$C$12 -> 0 | G49: =C49*SETTING!$C$13 -> 0 | J49: =SUM(D49:I49) -> 0
A50: =IF('TENAGA KERJA'!A49=0,"",'TENAGA KERJA'!A49) | B50: =IF('TENAGA KERJA'!B49=0,"",'TENAGA KERJA'!B49) | C50: =IF('TENAGA KERJA'!I49="Tidak",0,('TENAGA KERJA'!K49+'TENAGA KERJA'!L49)) -> 0 | D50: =C50*SETTING!$C$10 -> 0 | E50: =C50*SETTING!$C$11 -> 0 | F50: =C50*SETTING!$C$12 -> 0 | G50: =C50*SETTING!$C$13 -> 0 | J50: =SUM(D50:I50) -> 0
...

Sheet BPJS KES
A1: No | B1: Nama | C1: Upah yang Didaftarkan | D1: Iuran BPJS Kesehatan | F1: Total
D2: Pemberi Kerja | E2: Tenaga Kerja
A3: =IF('TENAGA KERJA'!A2=0,"",'TENAGA KERJA'!A2) -> 1 | B3: =IF('TENAGA KERJA'!B2=0,"",'TENAGA KERJA'!B2) -> ABDUL HALIM | C3: =IF('TENAGA KERJA'!J2="Tidak",0,('TENAGA KERJA'!K2+'TENAGA KERJA'!L2)) -> 4391337 | D3: =IF(C3=0,0,IF(C3<SETTING!$C$3,(SETTING!$C$3*SETTING!$C$5),IF(C3>SETTING!$C$4,(SETTING!$C$4*SETTING!$C$5),(C3*SETTING!$C$5)))) -> 175653.48 | E3: =IF(C3=0,0,IF(C3<SETTING!$C$3,(SETTING!$C$3*SETTING!$C$6),IF(C3>SETTING!$C$4,(SETTING!$C$4*SETTING!$C$6),(C3*SETTING!$C$6)))) -> 43913.37 | F3: =D3+E3 -> 219566.85
A4: =IF('TENAGA KERJA'!A3=0,"",'TENAGA KERJA'!A3) -> 2 | B4: =IF('TENAGA KERJA'!B3=0,"",'TENAGA KERJA'!B3) -> SRI ASLINDA | C4: =IF('TENAGA KERJA'!J3="Tidak",0,('TENAGA KERJA'!K3+'TENAGA KERJA'!L3)) -> 4391337 | D4: =IF(C4=0,0,IF(C4<SETTING!$C$3,(SETTING!$C$3*SETTING!$C$5),IF(C4>SETTING!$C$4,(SETTING!$C$4*SETTING!$C$5),(C4*SETTING!$C$5)))) -> 175653.48 | E4: =IF(C4=0,0,IF(C4<SETTING!$C$3,(SETTING!$C$3*SETTING!$C$6),IF(C4>SETTING!$C$4,(SETTING!$C$4*SETTING!$C$6),(C4*SETTING!$C$6)))) -> 43913.37 | F4: =D4+E4 -> 219566.85
A5: =IF('TENAGA KERJA'!A4=0,"",'TENAGA KERJA'!A4) -> 3 | B5: =IF('TENAGA KERJA'!B4=0,"",'TENAGA KERJA'!B4) -> RAFLY RAHMADAN GOBEL | C5: =IF('TENAGA KERJA'!J4="Tidak",0,('TENAGA KERJA'!K4+'TENAGA KERJA'!L4)) -> 4391337 | D5: =IF(C5=0,0,IF(C5<SETTING!$C$3,(SETTING!$C$3*SETTING!$C$5),IF(C5>SETTING!$C$4,(SETTING!$C$4*SETTING!$C$5),(C5*SETTING!$C$5)))) -> 175653.48 | E5: =IF(C5=0,0,IF(C5<SETTING!$C$3,(SETTING!$C$3*SETTING!$C$6),IF(C5>SETTING!$C$4,(SETTING!$C$4*SETTING!$C$6),(C5*SETTING!$C$6)))) -> 43913.37 | F5: =D5+E5 -> 219566.85
A6: =IF('TENAGA KERJA'!A5=0,"",'TENAGA KERJA'!A5) -> 4 | B6: =IF('TENAGA KERJA'!B5=0,"",'TENAGA KERJA'!B5) -> RAHMAT HIDAYAT | C6: =IF('TENAGA KERJA'!J5="Tidak",0,('TENAGA KERJA'!K5+'TENAGA KERJA'!L5)) -> 4391337 | D6: =IF(C6=0,0,IF(C6<SETTING!$C$3,(SETTING!$C$3*SETTING!$C$5),IF(C6>SETTING!$C$4,(SETTING!$C$4*SETTING!$C$5),(C6*SETTING!$C$5)))) -> 175653.48 | E6: =IF(C6=0,0,IF(C6<SETTING!$C$3,(SETTING!$C$3*SETTING!$C$6),IF(C6>SETTING!$C$4,(SETTING!$C$4*SETTING!$C$6),(C6*SETTING!$C$6)))) -> 43913.37 | F6: =D6+E6 -> 219566.85
A7: =IF('TENAGA KERJA'!A6=0,"",'TENAGA KERJA'!A6) -> 5 | B7: =IF('TENAGA KERJA'!B6=0,"",'TENAGA KERJA'!B6) -> ARYABAYA SRIPATI | C7: =IF('TENAGA KERJA'!J6="Tidak",0,('TENAGA KERJA'!K6+'TENAGA KERJA'!L6)) -> 4391337 | D7: =IF(C7=0,0,IF(C7<SETTING!$C$3,(SETTING!$C$3*SETTING!$C$5),IF(C7>SETTING!$C$4,(SETTING!$C$4*SETTING!$C$5),(C7*SETTING!$C$5)))) -> 175653.48 | E7: =IF(C7=0,0,IF(C7<SETTING!$C$3,(SETTING!$C$3*SETTING!$C$6),IF(C7>SETTING!$C$4,(SETTING!$C$4*SETTING!$C$6),(C7*SETTING!$C$6)))) -> 43913.37 | F7: =D7+E7 -> 219566.85
A8: =IF('TENAGA KERJA'!A7=0,"",'TENAGA KERJA'!A7) -> 6 | B8: =IF('TENAGA KERJA'!B7=0,"",'TENAGA KERJA'!B7) -> REZA NURHIDAYAT | C8: =IF('TENAGA KERJA'!J7="Tidak",0,('TENAGA KERJA'!K7+'TENAGA KERJA'!L7)) -> 4391337 | D8: =IF(C8=0,0,IF(C8<SETTING!$C$3,(SETTING!$C$3*SETTING!$C$5),IF(C8>SETTING!$C$4,(SETTING!$C$4*SETTING!$C$5),(C8*SETTING!$C$5)))) -> 175653.48 | E8: =IF(C8=0,0,IF(C8<SETTING!$C$3,(SETTING!$C$3*SETTING!$C$6),IF(C8>SETTING!$C$4,(SETTING!$C$4*SETTING!$C$6),(C8*SETTING!$C$6)))) -> 43913.37 | F8: =D8+E8 -> 219566.85
A9: =IF('TENAGA KERJA'!A8=0,"",'TENAGA KERJA'!A8) -> 7 | B9: =IF('TENAGA KERJA'!B8=0,"",'TENAGA KERJA'!B8) -> MUHAMMAD ANSHAR A | C9: =IF('TENAGA KERJA'!J8="Tidak",0,('TENAGA KERJA'!K8+'TENAGA KERJA'!L8)) -> 4391337 | D9: =IF(C9=0,0,IF(C9<SETTING!$C$3,(SETTING!$C$3*SETTING!$C$5),IF(C9>SETTING!$C$4,(SETTING!$C$4*SETTING!$C$5),(C9*SETTING!$C$5)))) -> 175653.48 | E9: =IF(C9=0,0,IF(C9<SETTING!$C$3,(SETTING!$C$3*SETTING!$C$6),IF(C9>SETTING!$C$4,(SETTING!$C$4*SETTING!$C$6),(C9*SETTING!$C$6)))) -> 43913.37 | F9: =D9+E9 -> 219566.85
A10: =IF('TENAGA KERJA'!A9=0,"",'TENAGA KERJA'!A9) -> 8 | B10: =IF('TENAGA KERJA'!B9=0,"",'TENAGA KERJA'!B9) -> IKA JULITA | C10: =IF('TENAGA KERJA'!J9="Tidak",0,('TENAGA KERJA'!K9+'TENAGA KERJA'!L9)) -> 4391337 | D10: =IF(C10=0,0,IF(C10<SETTING!$C$3,(SETTING!$C$3*SETTING!$C$5),IF(C10>SETTING!$C$4,(SETTING!$C$4*SETTING!$C$5),(C10*SETTING!$C$5)))) -> 175653.48 | E10: =IF(C10=0,0,IF(C10<SETTING!$C$3,(SETTING!$C$3*SETTING!$C$6),IF(C10>SETTING!$C$4,(SETTING!$C$4*SETTING!$C$6),(C10*SETTING!$C$6)))) -> 43913.37 | F10: =D10+E10 -> 219566.85
A11: =IF('TENAGA KERJA'!A10=0,"",'TENAGA KERJA'!A10) -> 9 | B11: =IF('TENAGA KERJA'!B10=0,"",'TENAGA KERJA'!B10) -> FAJAR SHADIQ HERNANDA | C11: =IF('TENAGA KERJA'!J10="Tidak",0,('TENAGA KERJA'!K10+'TENAGA KERJA'!L10)) -> 4391337 | D11: =IF(C11=0,0,IF(C11<SETTING!$C$3,(SETTING!$C$3*SETTING!$C$5),IF(C11>SETTING!$C$4,(SETTING!$C$4*SETTING!$C$5),(C11*SETTING!$C$5)))) -> 175653.48 | E11: =IF(C11=0,0,IF(C11<SETTING!$C$3,(SETTING!$C$3*SETTING!$C$6),IF(C11>SETTING!$C$4,(SETTING!$C$4*SETTING!$C$6),(C11*SETTING!$C$6)))) -> 43913.37 | F11: =D11+E11 -> 219566.85
A12: =IF('TENAGA KERJA'!A11=0,"",'TENAGA KERJA'!A11) -> 10 | B12: =IF('TENAGA KERJA'!B11=0,"",'TENAGA KERJA'!B11) -> BAGUS DWI ARISTA | C12: =IF('TENAGA KERJA'!J11="Tidak",0,('TENAGA KERJA'!K11+'TENAGA KERJA'!L11)) -> 4391337 | D12: =IF(C12=0,0,IF(C12<SETTING!$C$3,(SETTING!$C$3*SETTING!$C$5),IF(C12>SETTING!$C$4,(SETTING!$C$4*SETTING!$C$5),(C12*SETTING!$C$5)))) -> 175653.48 | E12: =IF(C12=0,0,IF(C12<SETTING!$C$3,(SETTING!$C$3*SETTING!$C$6),IF(C12>SETTING!$C$4,(SETTING!$C$4*SETTING!$C$6),(C12*SETTING!$C$6)))) -> 43913.37 | F12: =D12+E12 -> 219566.85
A13: =IF('TENAGA KERJA'!A12=0,"",'TENAGA KERJA'!A12) -> 11 | B13: =IF('TENAGA KERJA'!B12=0,"",'TENAGA KERJA'!B12) -> SITI AISYAH | C13: =IF('TENAGA KERJA'!J12="Tidak",0,('TENAGA KERJA'!K12+'TENAGA KERJA'!L12)) -> 4391337 | D13: =IF(C13=0,0,IF(C13<SETTING!$C$3,(SETTING!$C$3*SETTING!$C$5),IF(C13>SETTING!$C$4,(SETTING!$C$4*SETTING!$C$5),(C13*SETTING!$C$5)))) -> 175653.48 | E13: =IF(C13=0,0,IF(C13<SETTING!$C$3,(SETTING!$C$3*SETTING!$C$6),IF(C13>SETTING!$C$4,(SETTING!$C$4*SETTING!$C$6),(C13*SETTING!$C$6)))) -> 43913.37 | F13: =D13+E13 -> 219566.85
A14: =IF('TENAGA KERJA'!A13=0,"",'TENAGA KERJA'!A13) -> 12 | B14: =IF('TENAGA KERJA'!B13=0,"",'TENAGA KERJA'!B13) -> YUDI BISMANTAKA | C14: =IF('TENAGA KERJA'!J13="Tidak",0,('TENAGA KERJA'!K13+'TENAGA KERJA'!L13)) -> 4391337 | D14: =IF(C14=0,0,IF(C14<SETTING!$C$3,(SETTING!$C$3*SETTING!$C$5),IF(C14>SETTING!$C$4,(SETTING!$C$4*SETTING!$C$5),(C14*SETTING!$C$5)))) -> 175653.48 | E14: =IF(C14=0,0,IF(C14<SETTING!$C$3,(SETTING!$C$3*SETTING!$C$6),IF(C14>SETTING!$C$4,(SETTING!$C$4*SETTING!$C$6),(C14*SETTING!$C$6)))) -> 43913.37 | F14: =D14+E14 -> 219566.85
... A21: =IF('TENAGA KERJA'!A20=0,"",'TENAGA KERJA'!A20) -> 19 | B21: =IF('TENAGA KERJA'!B20=0,"",'TENAGA KERJA'!B20) -> MUAMMAR AKRAM | C21: =IF('TENAGA KERJA'!J20="Tidak",0,('TENAGA KERJA'!K20+'TENAGA KERJA'!L20)) -> 4391337 | D21: =IF(C21=0,0,IF(C21<SETTING!$C$3,(SETTING!$C$3*SETTING!$C$5),IF(C21>SETTING!$C$4,(SETTING!$C$4*SETTING!$C$5),(C21*SETTING!$C$5)))) -> 175653.48 | E21: =IF(C21=0,0,IF(C21<SETTING!$C$3,(SETTING!$C$3*SETTING!$C$6),IF(C21>SETTING!$C$4,(SETTING!$C$4*SETTING!$C$6),(C21*SETTING!$C$6)))) -> 43913.37 | F21: =D21+E21 -> 219566.85
A22: =IF('TENAGA KERJA'!A21=0,"",'TENAGA KERJA'!A21) -> 20 | B22: =IF('TENAGA KERJA'!B21=0,"",'TENAGA KERJA'!B21) -> DARMAWAN SYAH | C22: =IF('TENAGA KERJA'!J21="Tidak",0,('TENAGA KERJA'!K21+'TENAGA KERJA'!L21))+1891337 -> 4391337 | D22: =IF(C22=0,0,IF(C22<SETTING!$C$3,(SETTING!$C$3*SETTING!$C$5),IF(C22>SETTING!$C$4,(SETTING!$C$4*SETTING!$C$5),(C22*SETTING!$C$5)))) -> 175653.48 | E22: =IF(C22=0,0,IF(C22<SETTING!$C$3,(SETTING!$C$3*SETTING!$C$6),IF(C22>SETTING!$C$4,(SETTING!$C$4*SETTING!$C$6),(C22*SETTING!$C$6)))) -> 43913.37 | F22: =D22+E22 -> 219566.85
A23: =IF('TENAGA KERJA'!A22=0,"",'TENAGA KERJA'!A22) -> 21 | B23: =IF('TENAGA KERJA'!B22=0,"",'TENAGA KERJA'!B22) -> MARIYAM | C23: =IF('TENAGA KERJA'!J22="Tidak",0,('TENAGA KERJA'!K22+'TENAGA KERJA'!L22)) -> 4391337 | D23: =IF(C23=0,0,IF(C23<SETTING!$C$3,(SETTING!$C$3*SETTING!$C$5),IF(C23>SETTING!$C$4,(SETTING!$C$4*SETTING!$C$5),(C23*SETTING!$C$5)))) -> 175653.48 | E23: =IF(C23=0,0,IF(C23<SETTING!$C$3,(SETTING!$C$3*SETTING!$C$6),IF(C23>SETTING!$C$4,(SETTING!$C$4*SETTING!$C$6),(C23*SETTING!$C$6)))) -> 43913.37 | F23: =D23+E23 -> 219566.85
A24: =IF('TENAGA KERJA'!A23=0,"",'TENAGA KERJA'!A23) -> 22 | B24: =IF('TENAGA KERJA'!B23=0,"",'TENAGA KERJA'!B23) -> ACHMAD RENALDI | C24: =IF('TENAGA KERJA'!J23="Tidak",0,('TENAGA KERJA'!K23+'TENAGA KERJA'!L23)) -> 4391337 | D24: =IF(C24=0,0,IF(C24<SETTING!$C$3,(SETTING!$C$3*SETTING!$C$5),IF(C24>SETTING!$C$4,(SETTING!$C$4*SETTING!$C$5),(C24*SETTING!$C$5)))) -> 175653.48 | E24: =IF(C24=0,0,IF(C24<SETTING!$C$3,(SETTING!$C$3*SETTING!$C$6),IF(C24>SETTING!$C$4,(SETTING!$C$4*SETTING!$C$6),(C24*SETTING!$C$6)))) -> 43913.37 | F24: =D24+E24 -> 219566.85
A25: =IF('TENAGA KERJA'!A24=0,"",'TENAGA KERJA'!A24) -> 23 | B25: =IF('TENAGA KERJA'!B24=0,"",'TENAGA KERJA'!B24) -> ARIF GUNAWAN | C25: =IF('TENAGA KERJA'!J24="Tidak",0,('TENAGA KERJA'!K24+'TENAGA KERJA'!L24)) -> 4391337 | D25: =IF(C25=0,0,IF(C25<SETTING!$C$3,(SETTING!$C$3*SETTING!$C$5),IF(C25>SETTING!$C$4,(SETTING!$C$4*SETTING!$C$5),(C25*SETTING!$C$5)))) -> 175653.48 | E25: =IF(C25=0,0,IF(C25<SETTING!$C$3,(SETTING!$C$3*SETTING!$C$6),IF(C25>SETTING!$C$4,(SETTING!$C$4*SETTING!$C$6),(C25*SETTING!$C$6)))) -> 43913.37 | F25: =D25+E25 -> 219566.85
A26: =IF('TENAGA KERJA'!A25=0,"",'TENAGA KERJA'!A25) | B26: =IF('TENAGA KERJA'!B25=0,"",'TENAGA KERJA'!B25) | C26: =IF('TENAGA KERJA'!J25="Tidak",0,('TENAGA KERJA'!K25+'TENAGA KERJA'!L25)) -> 0 | D26: =IF(C26=0,0,IF(C26<SETTING!$C$3,(SETTING!$C$3*SETTING!$C$5),IF(C26>SETTING!$C$4,(SETTING!$C$4*SETTING!$C$5),(C26*SETTING!$C$5)))) -> 0 | E26: =IF(C26=0,0,IF(C26<SETTING!$C$3,(SETTING!$C$3*SETTING!$C$6),IF(C26>SETTING!$C$4,(SETTING!$C$4*SETTING!$C$6),(C26*SETTING!$C$6)))) -> 0 | F26: =D26+E26 -> 0 | G26: =SUM(D3:D25) -> 4040030
A27: =IF('TENAGA KERJA'!A26=0,"",'TENAGA KERJA'!A26) | B27: =IF('TENAGA KERJA'!B26=0,"",'TENAGA KERJA'!B26) | C27: =IF('TENAGA KERJA'!J26="Tidak",0,('TENAGA KERJA'!K26+'TENAGA KERJA'!L26)) -> 0 | D27: =IF(C27=0,0,IF(C27<SETTING!$C$3,(SETTING!$C$3*SETTING!$C$5),IF(C27>SETTING!$C$4,(SETTING!$C$4*SETTING!$C$5),(C27*SETTING!$C$5)))) -> 0 | E27: =IF(C27=0,0,IF(C27<SETTING!$C$3,(SETTING!$C$3*SETTING!$C$6),IF(C27>SETTING!$C$4,(SETTING!$C$4*SETTING!$C$6),(C27*SETTING!$C$6)))) -> 0 | F27: =D27+E27 -> 0
A28: =IF('TENAGA KERJA'!A27=0,"",'TENAGA KERJA'!A27) | B28: =IF('TENAGA KERJA'!B27=0,"",'TENAGA KERJA'!B27) | C28: =IF('TENAGA KERJA'!J27="Tidak",0,('TENAGA KERJA'!K27+'TENAGA KERJA'!L27)) -> 0 | D28: =IF(C28=0,0,IF(C28<SETTING!$C$3,(SETTING!$C$3*SETTING!$C$5),IF(C28>SETTING!$C$4,(SETTING!$C$4*SETTING!$C$5),(C28*SETTING!$C$5)))) -> 0 | E28: =IF(C28=0,0,IF(C28<SETTING!$C$3,(SETTING!$C$3*SETTING!$C$6),IF(C28>SETTING!$C$4,(SETTING!$C$4*SETTING!$C$6),(C28*SETTING!$C$6)))) -> 0 | F28: =D28+E28 -> 0
A29: =IF('TENAGA KERJA'!A28=0,"",'TENAGA KERJA'!A28) | B29: =IF('TENAGA KERJA'!B28=0,"",'TENAGA KERJA'!B28) | C29: =IF('TENAGA KERJA'!J28="Tidak",0,('TENAGA KERJA'!K28+'TENAGA KERJA'!L28)) -> 0 | D29: =IF(C29=0,0,IF(C29<SETTING!$C$3,(SETTING!$C$3*SETTING!$C$5),IF(C29>SETTING!$C$4,(SETTING!$C$4*SETTING!$C$5),(C29*SETTING!$C$5)))) -> 0 | E29: =IF(C29=0,0,IF(C29<SETTING!$C$3,(SETTING!$C$3*SETTING!$C$6),IF(C29>SETTING!$C$4,(SETTING!$C$4*SETTING!$C$6),(C29*SETTING!$C$6)))) -> 0 | F29: =D29+E29 -> 0
A30: =IF('TENAGA KERJA'!A29=0,"",'TENAGA KERJA'!A29) | B30: =IF('TENAGA KERJA'!B29=0,"",'TENAGA KERJA'!B29) | C30: =IF('TENAGA KERJA'!J29="Tidak",0,('TENAGA KERJA'!K29+'TENAGA KERJA'!L29)) -> 0 | D30: =IF(C30=0,0,IF(C30<SETTING!$C$3,(SETTING!$C$3*SETTING!$C$5),IF(C30>SETTING!$C$4,(SETTING!$C$4*SETTING!$C$5),(C30*SETTING!$C$5)))) -> 0 | E30: =IF(C30=0,0,IF(C30<SETTING!$C$3,(SETTING!$C$3*SETTING!$C$6),IF(C30>SETTING!$C$4,(SETTING!$C$4*SETTING!$C$6),(C30*SETTING!$C$6)))) -> 0 | F30: =D30+E30 -> 0
A31: =IF('TENAGA KERJA'!A30=0,"",'TENAGA KERJA'!A30) | B31: =IF('TENAGA KERJA'!B30=0,"",'TENAGA KERJA'!B30) | C31: =IF('TENAGA KERJA'!J30="Tidak",0,('TENAGA KERJA'!K30+'TENAGA KERJA'!L30)) -> 0 | D31: =IF(C31=0,0,IF(C31<SETTING!$C$3,(SETTING!$C$3*SETTING!$C$5),IF(C31>SETTING!$C$4,(SETTING!$C$4*SETTING!$C$5),(C31*SETTING!$C$5)))) -> 0 | E31: =IF(C31=0,0,IF(C31<SETTING!$C$3,(SETTING!$C$3*SETTING!$C$6),IF(C31>SETTING!$C$4,(SETTING!$C$4*SETTING!$C$6),(C31*SETTING!$C$6)))) -> 0 | F31: =D31+E31 -> 0
A32: =IF('TENAGA KERJA'!A31=0,"",'TENAGA KERJA'!A31) | B32: =IF('TENAGA KERJA'!B31=0,"",'TENAGA KERJA'!B31) | C32: =IF('TENAGA KERJA'!J31="Tidak",0,('TENAGA KERJA'!K31+'TENAGA KERJA'!L31)) -> 0 | D32: =IF(C32=0,0,IF(C32<SETTING!$C$3,(SETTING!$C$3*SETTING!$C$5),IF(C32>SETTING!$C$4,(SETTING!$C$4*SETTING!$C$5),(C32*SETTING!$C$5)))) -> 0 | E32: =IF(C32=0,0,IF(C32<SETTING!$C$3,(SETTING!$C$3*SETTING!$C$6),IF(C32>SETTING!$C$4,(SETTING!$C$4*SETTING!$C$6),(C32*SETTING!$C$6)))) -> 0 | F32: =D32+E32 -> 0
A33: =IF('TENAGA KERJA'!A32=0,"",'TENAGA KERJA'!A32) | B33: =IF('TENAGA KERJA'!B32=0,"",'TENAGA KERJA'!B32) | C33: =IF('TENAGA KERJA'!J32="Tidak",0,('TENAGA KERJA'!K32+'TENAGA KERJA'!L32)) -> 0 | D33: =IF(C33=0,0,IF(C33<SETTING!$C$3,(SETTING!$C$3*SETTING!$C$5),IF(C33>SETTING!$C$4,(SETTING!$C$4*SETTING!$C$5),(C33*SETTING!$C$5)))) -> 0 | E33: =IF(C33=0,0,IF(C33<SETTING!$C$3,(SETTING!$C$3*SETTING!$C$6),IF(C33>SETTING!$C$4,(SETTING!$C$4*SETTING!$C$6),(C33*SETTING!$C$6)))) -> 0 | F33: =D33+E33 -> 0
A34: =IF('TENAGA KERJA'!A33=0,"",'TENAGA KERJA'!A33) | B34: =IF('TENAGA KERJA'!B33=0,"",'TENAGA KERJA'!B33) | C34: =IF('TENAGA KERJA'!J33="Tidak",0,('TENAGA KERJA'!K33+'TENAGA KERJA'!L33)) -> 0 | D34: =IF(C34=0,0,IF(C34<SETTING!$C$3,(SETTING!$C$3*SETTING!$C$5),IF(C34>SETTING!$C$4,(SETTING!$C$4*SETTING!$C$5),(C34*SETTING!$C$5)))) -> 0 | E34: =IF(C34=0,0,IF(C34<SETTING!$C$3,(SETTING!$C$3*SETTING!$C$6),IF(C34>SETTING!$C$4,(SETTING!$C$4*SETTING!$C$6),(C34*SETTING!$C$6)))) -> 0 | F34: =D34+E34 -> 0
A35: =IF('TENAGA KERJA'!A34=0,"",'TENAGA KERJA'!A34) | B35: =IF('TENAGA KERJA'!B34=0,"",'TENAGA KERJA'!B34) | C35: =IF('TENAGA KERJA'!J34="Tidak",0,('TENAGA KERJA'!K34+'TENAGA KERJA'!L34)) -> 0 | D35: =IF(C35=0,0,IF(C35<SETTING!$C$3,(SETTING!$C$3*SETTING!$C$5),IF(C35>SETTING!$C$4,(SETTING!$C$4*SETTING!$C$5),(C35*SETTING!$C$5)))) -> 0 | E35: =IF(C35=0,0,IF(C35<SETTING!$C$3,(SETTING!$C$3*SETTING!$C$6),IF(C35>SETTING!$C$4,(SETTING!$C$4*SETTING!$C$6),(C35*SETTING!$C$6)))) -> 0 | F35: =D35+E35 -> 0
A36: =IF('TENAGA KERJA'!A35=0,"",'TENAGA KERJA'!A35) | B36: =IF('TENAGA KERJA'!B35=0,"",'TENAGA KERJA'!B35) | C36: =IF('TENAGA KERJA'!J35="Tidak",0,('TENAGA KERJA'!K35+'TENAGA KERJA'!L35)) -> 0 | D36: =IF(C36=0,0,IF(C36<SETTING!$C$3,(SETTING!$C$3*SETTING!$C$5),IF(C36>SETTING!$C$4,(SETTING!$C$4*SETTING!$C$5),(C36*SETTING!$C$5)))) -> 0 | E36: =IF(C36=0,0,IF(C36<SETTING!$C$3,(SETTING!$C$3*SETTING!$C$6),IF(C36>SETTING!$C$4,(SETTING!$C$4*SETTING!$C$6),(C36*SETTING!$C$6)))) -> 0 | F36: =D36+E36 -> 0
A37: =IF('TENAGA KERJA'!A36=0,"",'TENAGA KERJA'!A36) | B37: =IF('TENAGA KERJA'!B36=0,"",'TENAGA KERJA'!B36) | C37: =IF('TENAGA KERJA'!J36="Tidak",0,('TENAGA KERJA'!K36+'TENAGA KERJA'!L36)) -> 0 | D37: =IF(C37=0,0,IF(C37<SETTING!$C$3,(SETTING!$C$3*SETTING!$C$5),IF(C37>SETTING!$C$4,(SETTING!$C$4*SETTING!$C$5),(C37*SETTING!$C$5)))) -> 0 | E37: =IF(C37=0,0,IF(C37<SETTING!$C$3,(SETTING!$C$3*SETTING!$C$6),IF(C37>SETTING!$C$4,(SETTING!$C$4*SETTING!$C$6),(C37*SETTING!$C$6)))) -> 0 | F37: =D37+E37 -> 0
A38: =IF('TENAGA KERJA'!A37=0,"",'TENAGA KERJA'!A37) | B38: =IF('TENAGA KERJA'!B37=0,"",'TENAGA KERJA'!B37) | C38: =IF('TENAGA KERJA'!J37="Tidak",0,('TENAGA KERJA'!K37+'TENAGA KERJA'!L37)) -> 0 | D38: =IF(C38=0,0,IF(C38<SETTING!$C$3,(SETTING!$C$3*SETTING!$C$5),IF(C38>SETTING!$C$4,(SETTING!$C$4*SETTING!$C$5),(C38*SETTING!$C$5)))) -> 0 | E38: =IF(C38=0,0,IF(C38<SETTING!$C$3,(SETTING!$C$3*SETTING!$C$6),IF(C38>SETTING!$C$4,(SETTING!$C$4*SETTING!$C$6),(C38*SETTING!$C$6)))) -> 0 | F38: =D38+E38 -> 0
... A51: =IF('TENAGA KERJA'!A50=0,"",'TENAGA KERJA'!A50) | B51: =IF('TENAGA KERJA'!B50=0,"",'TENAGA KERJA'!B50) | C51: =IF('TENAGA KERJA'!J50="Tidak",0,('TENAGA KERJA'!K50+'TENAGA KERJA'!L50)) -> 0 | D51: =IF(C51=0,0,IF(C51<SETTING!$C$3,(SETTING!$C$3*SETTING!$C$5),IF(C51>SETTING!$C$4,(SETTING!$C$4*SETTING!$C$5),(C51*SETTING!$C$5)))) -> 0 | E51: =IF(C51=0,0,IF(C51<SETTING!$C$3,(SETTING!$C$3*SETTING!$C$6),IF(C51>SETTING!$C$4,(SETTING!$C$4*SETTING!$C$6),(C51*SETTING!$C$6)))) -> 0 | F51: =D51+E51 -> 0
A52: =IF('TENAGA KERJA'!A51=0,"",'TENAGA KERJA'!A51) | B52: =IF('TENAGA KERJA'!B51=0,"",'TENAGA KERJA'!B51) | C52: =IF('TENAGA KERJA'!J51="Tidak",0,('TENAGA KERJA'!K51+'TENAGA KERJA'!L51)) -> 0 | D52: =IF(C52=0,0,IF(C52<SETTING!$C$3,(SETTING!$C$3*SETTING!$C$5),IF(C52>SETTING!$C$4,(SETTING!$C$4*SETTING!$C$5),(C52*SETTING!$C$5)))) -> 0 | E52: =IF(C52=0,0,IF(C52<SETTING!$C$3,(SETTING!$C$3*SETTING!$C$6),IF(C52>SETTING!$C$4,(SETTING!$C$4*SETTING!$C$6),(C52*SETTING!$C$6))))*2 -> 0 | F52: =D52+E52 -> 0
A53: =IF('TENAGA KERJA'!A52=0,"",'TENAGA KERJA'!A52) | B53: =IF('TENAGA KERJA'!B52=0,"",'TENAGA KERJA'!B52) | C53: =IF('TENAGA KERJA'!J52="Tidak",0,('TENAGA KERJA'!K52+'TENAGA KERJA'!L52)) -> 0 | D53: =IF(C53=0,0,IF(C53<SETTING!$C$3,(SETTING!$C$3*SETTING!$C$5),IF(C53>SETTING!$C$4,(SETTING!$C$4*SETTING!$C$5),(C53*SETTING!$C$5)))) -> 0 | E53: =IF(C53=0,0,IF(C53<SETTING!$C$3,(SETTING!$C$3*SETTING!$C$6),IF(C53>SETTING!$C$4,(SETTING!$C$4*SETTING!$C$6),(C53*SETTING!$C$6)))) -> 0 | F53: =D53+E53 -> 0
A54: =IF('TENAGA KERJA'!A53=0,"",'TENAGA KERJA'!A53) | B54: =IF('TENAGA KERJA'!B53=0,"",'TENAGA KERJA'!B53) | C54: =IF('TENAGA KERJA'!J53="Tidak",0,('TENAGA KERJA'!K53+'TENAGA KERJA'!L53)) -> 0 | D54: =IF(C54=0,0,IF(C54<SETTING!$C$3,(SETTING!$C$3*SETTING!$C$5),IF(C54>SETTING!$C$4,(SETTING!$C$4*SETTING!$C$5),(C54*SETTING!$C$5)))) -> 0 | E54: =IF(C54=0,0,IF(C54<SETTING!$C$3,(SETTING!$C$3*SETTING!$C$6),IF(C54>SETTING!$C$4,(SETTING!$C$4*SETTING!$C$6),(C54*SETTING!$C$6)))) -> 0 | F54: =D54+E54 -> 0
A55: =IF('TENAGA KERJA'!A54=0,"",'TENAGA KERJA'!A54) | B55: =IF('TENAGA KERJA'!B54=0,"",'TENAGA KERJA'!B54) | C55: =IF('TENAGA KERJA'!J54="Tidak",0,('TENAGA KERJA'!K54+'TENAGA KERJA'!L54)) -> 0 | D55: =IF(C55=0,0,IF(C55<SETTING!$C$3,(SETTING!$C$3*SETTING!$C$5),IF(C55>SETTING!$C$4,(SETTING!$C$4*SETTING!$C$5),(C55*SETTING!$C$5)))) -> 0 | E55: =IF(C55=0,0,IF(C55<SETTING!$C$3,(SETTING!$C$3*SETTING!$C$6),IF(C55>SETTING!$C$4,(SETTING!$C$4*SETTING!$C$6),(C55*SETTING!$C$6)))) -> 0 | F55: =D55+E55 -> 0
A56: =IF('TENAGA KERJA'!A55=0,"",'TENAGA KERJA'!A55) | B56: =IF('TENAGA KERJA'!B55=0,"",'TENAGA KERJA'!B55) | C56: =IF('TENAGA KERJA'!J55="Tidak",0,('TENAGA KERJA'!K55+'TENAGA KERJA'!L55)) -> 0 | D56: =IF(C56=0,0,IF(C56<SETTING!$C$3,(SETTING!$C$3*SETTING!$C$5),IF(C56>SETTING!$C$4,(SETTING!$C$4*SETTING!$C$5),(C56*SETTING!$C$5)))) -> 0 | E56: =IF(C56=0,0,IF(C56<SETTING!$C$3,(SETTING!$C$3*SETTING!$C$6),IF(C56>SETTING!$C$4,(SETTING!$C$4*SETTING!$C$6),(C56*SETTING!$C$6)))) -> 0 | F56: =D56+E56 -> 0
A57: =IF('TENAGA KERJA'!A56=0,"",'TENAGA KERJA'!A56) | B57: =IF('TENAGA KERJA'!B56=0,"",'TENAGA KERJA'!B56) | C57: =IF('TENAGA KERJA'!J56="Tidak",0,('TENAGA KERJA'!K56+'TENAGA KERJA'!L56)) -> 0 | D57: =IF(C57=0,0,IF(C57<SETTING!$C$3,(SETTING!$C$3*SETTING!$C$5),IF(C57>SETTING!$C$4,(SETTING!$C$4*SETTING!$C$5),(C57*SETTING!$C$5)))) -> 0 | E57: =IF(C57=0,0,IF(C57<SETTING!$C$3,(SETTING!$C$3*SETTING!$C$6),IF(C57>SETTING!$C$4,(SETTING!$C$4*SETTING!$C$6),(C57*SETTING!$C$6)))) -> 0 | F57: =D57+E57 -> 0
A58: =IF('TENAGA KERJA'!A57=0,"",'TENAGA KERJA'!A57) | B58: =IF('TENAGA KERJA'!B57=0,"",'TENAGA KERJA'!B57) | C58: =IF('TENAGA KERJA'!J57="Tidak",0,('TENAGA KERJA'!K57+'TENAGA KERJA'!L57)) -> 0 | D58: =IF(C58=0,0,IF(C58<SETTING!$C$3,(SETTING!$C$3*SETTING!$C$5),IF(C58>SETTING!$C$4,(SETTING!$C$4*SETTING!$C$5),(C58*SETTING!$C$5)))) -> 0 | E58: =IF(C58=0,0,IF(C58<SETTING!$C$3,(SETTING!$C$3*SETTING!$C$6),IF(C58>SETTING!$C$4,(SETTING!$C$4*SETTING!$C$6),(C58*SETTING!$C$6)))) -> 0 | F58: =D58+E58 -> 0
...

Sheet PPH PSL 21 - GROSS (MULAI 2024)
A1: No | B1: Nama | C1: Gaji Pokok | D1: Tunjangan tetap | E1: lembur, THR. Bonus | F1: Natura, Dll | G1: Ditanggung Pemberi Kerja | J1: Jum. Penghasilan Bruto Bulanan | K1: Tarif Efektif | L1: PPh Psl 21 Terhutang
G2: JKK | H2: JKM | I2: BPJS Kesehatan
A3: =IF('TENAGA KERJA'!A2=0,"",'TENAGA KERJA'!A2) -> 1 | B3: =IF('TENAGA KERJA'!B2=0,"",'TENAGA KERJA'!B2) -> ABDUL HALIM | C3: ='TENAGA KERJA'!K2 -> 2961337 | D3: ='TENAGA KERJA'!L2 -> 1430000 | E3: ='TENAGA KERJA'!M2 -> 1154947 | F3: ='TENAGA KERJA'!N2 -> 1550000 | G3: ='BPJS TK'!D3 -> 39082.899 | H3: ='BPJS TK'!E3 -> 13174.011 | I3: ='BPJS KES'!D3 -> 175653.48 | J3: =SUM(C3:I3) -> 7324194.4 | K3: =IF('TENAGA KERJA'!H2="KATEGORI A",VLOOKUP(J3,'TER 2024'!$B$2:$E$45,4),IF('TENAGA KERJA'!H2="KATEGORI B",VLOOKUP(J3,'TER 2024'!$B$46:$E$85,4),IF('TENAGA KERJA'!H2="KATEGORI C",VLOOKUP(J3,'TER 2024'!$B$86:$E$126,4),0))) -> 0.005 | L3: =IF('TENAGA KERJA'!F2="NPWP",'PPH PSL 21 - GROSS (MULAI 2024)'!J3*K3,IF('TENAGA KERJA'!F2="NON-NPWP",'PPH PSL 21 - GROSS (MULAI 2024)'!J3*K3*120%,0)) -> 36620.972
A4: =IF('TENAGA KERJA'!A3=0,"",'TENAGA KERJA'!A3) -> 2 | B4: =IF('TENAGA KERJA'!B3=0,"",'TENAGA KERJA'!B3) -> SRI ASLINDA | C4: ='TENAGA KERJA'!K3 -> 2961337 | D4: ='TENAGA KERJA'!L3 -> 1430000 | E4: ='TENAGA KERJA'!M3 -> 300000 | F4: ='TENAGA KERJA'!N3 -> 1550000 | G4: ='BPJS TK'!D4 -> 39082.899 | H4: ='BPJS TK'!E4 -> 13174.011 | I4: ='BPJS KES'!D4 -> 175653.48 | J4: =SUM(C4:I4) -> 6469247.4 | K4: =IF('TENAGA KERJA'!H3="KATEGORI A",VLOOKUP(J4,'TER 2024'!$B$2:$E$45,4),IF('TENAGA KERJA'!H3="KATEGORI B",VLOOKUP(J4,'TER 2024'!$B$46:$E$85,4),IF('TENAGA KERJA'!H3="KATEGORI C",VLOOKUP(J4,'TER 2024'!$B$86:$E$126,4),0))) -> 0.01 | L4: =IF('TENAGA KERJA'!F3="NPWP",'PPH PSL 21 - GROSS (MULAI 2024)'!J4*K4,IF('TENAGA KERJA'!F3="NON-NPWP",'PPH PSL 21 - GROSS (MULAI 2024)'!J4*K4*120%,0)) -> 64692.474 | JQ4: `
A5: =IF('TENAGA KERJA'!A4=0,"",'TENAGA KERJA'!A4) -> 3 | B5: =IF('TENAGA KERJA'!B4=0,"",'TENAGA KERJA'!B4) -> RAFLY RAHMADAN GOBEL | C5: ='TENAGA KERJA'!K4 -> 2961337 | D5: ='TENAGA KERJA'!L4 -> 1430000 | E5: ='TENAGA KERJA'!M4 -> 1231097.4 | F5: ='TENAGA KERJA'!N4 -> 1550000 | G5: ='BPJS TK'!D5 -> 39082.899 | H5: ='BPJS TK'!E5 -> 13174.011 | I5: ='BPJS KES'!D5 -> 175653.48 | J5: =SUM(C5:I5) -> 7400344.8 | K5: =IF('TENAGA KERJA'!H4="KATEGORI A",VLOOKUP(J5,'TER 2024'!$B$2:$E$45,4),IF('TENAGA KERJA'!H4="KATEGORI B",VLOOKUP(J5,'TER 2024'!$B$46:$E$85,4),IF('TENAGA KERJA'!H4="KATEGORI C",VLOOKUP(J5,'TER 2024'!$B$86:$E$126,4),0))) -> 0.0125 | L5: =IF('TENAGA KERJA'!F4="NPWP",'PPH PSL 21 - GROSS (MULAI 2024)'!J5*K5,IF('TENAGA KERJA'!F4="NON-NPWP",'PPH PSL 21 - GROSS (MULAI 2024)'!J5*K5*120%,0)) -> 92504.309
A6: =IF('TENAGA KERJA'!A5=0,"",'TENAGA KERJA'!A5) -> 4 | B6: =IF('TENAGA KERJA'!B5=0,"",'TENAGA KERJA'!B5) -> RAHMAT HIDAYAT | C6: ='TENAGA KERJA'!K5 -> 2961337 | D6: ='TENAGA KERJA'!L5 -> 1430000 | E6: ='TENAGA KERJA'!M5 -> 1637232.6 | F6: ='TENAGA KERJA'!N5 -> 1550000 | G6: ='BPJS TK'!D6 -> 39082.899 | H6: ='BPJS TK'!E6 -> 13174.011 | I6: ='BPJS KES'!D6 -> 175653.48 | J6: =SUM(C6:I6) -> 7806480 | K6: =IF('TENAGA KERJA'!H5="KATEGORI A",VLOOKUP(J6,'TER 2024'!$B$2:$E$45,4),IF('TENAGA KERJA'!H5="KATEGORI B",VLOOKUP(J6,'TER 2024'!$B$46:$E$85,4),IF('TENAGA KERJA'!H5="KATEGORI C",VLOOKUP(J6,'TER 2024'!$B$86:$E$126,4),0))) -> 0.015 | L6: =IF('TENAGA KERJA'!F5="NPWP",'PPH PSL 21 - GROSS (MULAI 2024)'!J6*K6,IF('TENAGA KERJA'!F5="NON-NPWP",'PPH PSL 21 - GROSS (MULAI 2024)'!J6*K6*120%,0)) -> 117097.2
A7: =IF('TENAGA KERJA'!A6=0,"",'TENAGA KERJA'!A6) -> 5 | B7: =IF('TENAGA KERJA'!B6=0,"",'TENAGA KERJA'!B6) -> ARYABAYA SRIPATI | C7: ='TENAGA KERJA'!K6 -> 2961337 | D7: ='TENAGA KERJA'!L6 -> 1430000 | E7: ='TENAGA KERJA'!M6 -> 342676.59 | F7: ='TENAGA KERJA'!N6 -> 1550000 | G7: ='BPJS TK'!D7 -> 39082.899 | H7: ='BPJS TK'!E7 -> 13174.011 | I7: ='BPJS KES'!D7 -> 175653.48 | J7: =SUM(C7:I7) -> 6511924 | K7: =IF('TENAGA KERJA'!H6="KATEGORI A",VLOOKUP(J7,'TER 2024'!$B$2:$E$45,4),IF('TENAGA KERJA'!H6="KATEGORI B",VLOOKUP(J7,'TER 2024'!$B$46:$E$85,4),IF('TENAGA KERJA'!H6="KATEGORI C",VLOOKUP(J7,'TER 2024'!$B$86:$E$126,4),0))) -> 0.01 | L7: =IF('TENAGA KERJA'!F6="NPWP",'PPH PSL 21 - GROSS (MULAI 2024)'!J7*K7,IF('TENAGA KERJA'!F6="NON-NPWP",'PPH PSL 21 - GROSS (MULAI 2024)'!J7*K7*120%,0)) -> 65119.24
A8: =IF('TENAGA KERJA'!A7=0,"",'TENAGA KERJA'!A7) -> 6 | B8: =IF('TENAGA KERJA'!B7=0,"",'TENAGA KERJA'!B7) -> REZA NURHIDAYAT | C8: ='TENAGA KERJA'!K7 -> 2961337 | D8: ='TENAGA KERJA'!L7 -> 1430000 | E8: ='TENAGA KERJA'!M7 -> 850345.6 | F8: ='TENAGA KERJA'!N7 -> 1550000 | G8: ='BPJS TK'!D8 -> 39082.899 | H8: ='BPJS TK'!E8 -> 13174.011 | I8: ='BPJS KES'!D8 -> 175653.48 | J8: =SUM(C8:I8) -> 7019593 | K8: =IF('TENAGA KERJA'!H7="KATEGORI A",VLOOKUP(J8,'TER 2024'!$B$2:$E$45,4),IF('TENAGA KERJA'!H7="KATEGORI B",VLOOKUP(J8,'TER 2024'!$B$46:$E$85,4),IF('TENAGA KERJA'!H7="KATEGORI C",VLOOKUP(J8,'TER 2024'!$B$86:$E$126,4),0))) -> 0.0125 | L8: =IF('TENAGA KERJA'!F7="NPWP",'PPH PSL 21 - GROSS (MULAI 2024)'!J8*K8,IF('TENAGA KERJA'!F7="NON-NPWP",'PPH PSL 21 - GROSS (MULAI 2024)'!J8*K8*120%,0)) -> 87744.912
